2025-09-19 15:30:39,697 [INFO] app: 📝 Logging configured (level=INFO)
2025-09-19 15:30:39,699 [INFO] app: 🔗 Database URI: postgresql://postgres:****@localhost:5432/budget_db
2025-09-19 15:30:39,791 [INFO] app: 🌍 CORS enabled for origins: http://localhost:5173, http://localhost:5174
2025-09-19 15:30:39,805 [INFO] app: 🧩 Blueprints registered: ['auth', 'budget', 'home']
2025-09-19 15:30:39,818 [INFO] app: ⏰ Scheduler started successfully
2025-09-19 15:30:39,819 [INFO] app: 🚀 Starting Budget Tracker API at http://127.0.0.1:5000 (debug=True)
2025-09-19 15:33:04,027 [INFO] app: 📝 Logging configured (level=INFO)
2025-09-19 15:33:04,029 [INFO] app: 🔗 Database URI: postgresql://postgres:****@localhost:5432/budget_db
2025-09-19 15:33:04,187 [INFO] app: 🌍 CORS enabled for origins: http://localhost:5173, http://localhost:5174
2025-09-19 15:33:04,195 [INFO] app: 🧩 Blueprints registered: ['auth', 'budget', 'home']
2025-09-19 15:33:04,211 [INFO] app: ⏰ Scheduler started successfully
2025-09-19 15:33:04,214 [INFO] app: 🚀 Starting Budget Tracker API at http://127.0.0.1:5000 (debug=True)
2025-09-19 15:33:51,316 [INFO] app: 📝 Logging configured (level=INFO)
2025-09-19 15:33:51,334 [INFO] app: 🔗 Database URI: postgresql://postgres:****@localhost:5432/budget_db
2025-09-19 15:33:51,413 [INFO] app: 🌍 CORS enabled for origins: http://localhost:5173, http://localhost:5174
2025-09-19 15:33:51,420 [INFO] app: 🧩 Blueprints registered: ['auth', 'budget', 'home']
2025-09-19 15:33:51,431 [INFO] app: ⏰ Scheduler started successfully
2025-09-19 15:33:51,432 [INFO] app: 🚀 Starting Budget Tracker API at http://127.0.0.1:5000 (debug=True)
2025-09-19 15:33:55,618 [INFO] app: 📝 Logging configured (level=INFO)
2025-09-19 15:33:55,619 [INFO] app: 🔗 Database URI: postgresql://postgres:****@localhost:5432/budget_db
2025-09-19 15:33:55,682 [INFO] app: 🌍 CORS enabled for origins: http://localhost:5173, http://localhost:5174
2025-09-19 15:33:55,700 [INFO] app: 🧩 Blueprints registered: ['auth', 'budget', 'home']
2025-09-19 15:33:55,710 [INFO] app: ⏰ Scheduler started successfully
2025-09-19 15:33:55,711 [INFO] app: 🚀 Starting Budget Tracker API at http://127.0.0.1:5000 (debug=True)
2025-09-19 15:43:19,574 [INFO] app: 📝 Logging configured (level=INFO)
2025-09-19 15:43:19,594 [INFO] app: 🔗 Database URI: postgresql://postgres:****@localhost:5432/budget_db
2025-09-19 15:43:19,743 [INFO] app: 🌍 CORS enabled for origins: http://localhost:5173, http://localhost:5174
2025-09-19 15:43:19,763 [INFO] app: 🧩 Blueprints registered: ['auth', 'budget', 'home']
2025-09-19 15:43:19,830 [INFO] app: ⏰ Scheduler started successfully
2025-09-19 15:43:19,832 [INFO] app: 🚀 Starting Budget Tracker API at http://127.0.0.1:5000 (debug=True)
2025-09-19 15:44:23,970 [INFO] app: 📝 Logging configured (level=INFO)
2025-09-19 15:44:23,973 [INFO] app: 🔗 Database URI: postgresql://postgres:****@localhost:5432/budget_db
2025-09-19 15:44:24,098 [INFO] app: 🌍 CORS enabled for origins: http://localhost:5173, http://localhost:5174
2025-09-19 15:44:24,107 [INFO] app: 🧩 Blueprints registered: ['auth', 'budget', 'home']
2025-09-19 15:44:24,118 [INFO] app: ⏰ Scheduler started successfully
2025-09-19 15:44:24,119 [INFO] app: 🚀 Starting Budget Tracker API at http://127.0.0.1:5000 (debug=True)
2025-09-19 15:44:30,633 [INFO] app: 📝 Logging configured (level=INFO)
2025-09-19 15:44:30,633 [INFO] app: 🔗 Database URI: postgresql://postgres:****@localhost:5432/budget_db
2025-09-19 15:44:30,676 [INFO] app: 🌍 CORS enabled for origins: http://localhost:5173, http://localhost:5174
2025-09-19 15:44:30,691 [INFO] app: 🧩 Blueprints registered: ['auth', 'budget', 'home']
2025-09-19 15:44:30,704 [INFO] app: ⏰ Scheduler started successfully
2025-09-19 15:44:30,706 [INFO] app: 🚀 Starting Budget Tracker API at http://127.0.0.1:5000 (debug=True)
2025-09-19 16:01:06,612 [INFO] app: 📝 Logging configured (level=INFO)
2025-09-19 16:01:06,615 [CRITICAL] app: ❌ No SQLALCHEMY_DATABASE_URI configured. Exiting...
2025-09-19 16:44:12,766 [INFO] app: 📝 Logging configured (level=INFO)
2025-09-19 16:44:12,768 [CRITICAL] app: ❌ No SQLALCHEMY_DATABASE_URI configured. Exiting...
2025-09-19 16:50:26,941 [INFO] app: 📝 Logging configured (level=INFO)
2025-09-19 16:50:26,958 [INFO] app: 🔗 Database URI: postgresql://postgres:****@localhost:5432/budgettracker
2025-09-19 16:50:27,094 [INFO] app: 🌍 CORS enabled for origins: http://localhost:5173, http://127.0.0.1:5173
2025-09-19 16:50:27,106 [INFO] app: 🧩 Blueprints registered: ['auth', 'budget', 'home']
2025-09-19 16:50:27,116 [INFO] app: ⏰ Scheduler started successfully
2025-09-19 16:50:27,117 [INFO] app: 🚀 Starting Budget Tracker API at http://127.0.0.1:5000 (debug=False)
2025-09-19 17:10:22,275 [ERROR] app: ❌ Error in /auth/login: (psycopg2.OperationalError) connection to server at "localhost" (::1), port 5432 failed: FATAL:  database "budgettracker" does not exist

(Background on this error at: https://sqlalche.me/e/20/e3q8)
Traceback (most recent call last):
  File "D:\BudgetTracker_Backend\.venv\Lib\site-packages\sqlalchemy\engine\base.py", line 143, in __init__
    self._dbapi_connection = engine.raw_connection()
                             ~~~~~~~~~~~~~~~~~~~~~^^
  File "D:\BudgetTracker_Backend\.venv\Lib\site-packages\sqlalchemy\engine\base.py", line 3301, in raw_connection
    return self.pool.connect()
           ~~~~~~~~~~~~~~~~~^^
  File "D:\BudgetTracker_Backend\.venv\Lib\site-packages\sqlalchemy\pool\base.py", line 447, in connect
    return _ConnectionFairy._checkout(self)
           ~~~~~~~~~~~~~~~~~~~~~~~~~~^^^^^^
  File "D:\BudgetTracker_Backend\.venv\Lib\site-packages\sqlalchemy\pool\base.py", line 1264, in _checkout
    fairy = _ConnectionRecord.checkout(pool)
  File "D:\BudgetTracker_Backend\.venv\Lib\site-packages\sqlalchemy\pool\base.py", line 711, in checkout
    rec = pool._do_get()
  File "D:\BudgetTracker_Backend\.venv\Lib\site-packages\sqlalchemy\pool\impl.py", line 177, in _do_get
    with util.safe_reraise():
         ~~~~~~~~~~~~~~~~~^^
  File "D:\BudgetTracker_Backend\.venv\Lib\site-packages\sqlalchemy\util\langhelpers.py", line 224, in __exit__
    raise exc_value.with_traceback(exc_tb)
  File "D:\BudgetTracker_Backend\.venv\Lib\site-packages\sqlalchemy\pool\impl.py", line 175, in _do_get
    return self._create_connection()
           ~~~~~~~~~~~~~~~~~~~~~~~^^
  File "D:\BudgetTracker_Backend\.venv\Lib\site-packages\sqlalchemy\pool\base.py", line 388, in _create_connection
    return _ConnectionRecord(self)
  File "D:\BudgetTracker_Backend\.venv\Lib\site-packages\sqlalchemy\pool\base.py", line 673, in __init__
    self.__connect()
    ~~~~~~~~~~~~~~^^
  File "D:\BudgetTracker_Backend\.venv\Lib\site-packages\sqlalchemy\pool\base.py", line 899, in __connect
    with util.safe_reraise():
         ~~~~~~~~~~~~~~~~~^^
  File "D:\BudgetTracker_Backend\.venv\Lib\site-packages\sqlalchemy\util\langhelpers.py", line 224, in __exit__
    raise exc_value.with_traceback(exc_tb)
  File "D:\BudgetTracker_Backend\.venv\Lib\site-packages\sqlalchemy\pool\base.py", line 895, in __connect
    self.dbapi_connection = connection = pool._invoke_creator(self)
                                         ~~~~~~~~~~~~~~~~~~~~^^^^^^
  File "D:\BudgetTracker_Backend\.venv\Lib\site-packages\sqlalchemy\engine\create.py", line 661, in connect
    return dialect.connect(*cargs, **cparams)
           ~~~~~~~~~~~~~~~^^^^^^^^^^^^^^^^^^^
  File "D:\BudgetTracker_Backend\.venv\Lib\site-packages\sqlalchemy\engine\default.py", line 629, in connect
    return self.loaded_dbapi.connect(*cargs, **cparams)  # type: ignore[no-any-return]  # NOQA: E501
           ~~~~~~~~~~~~~~~~~~~~~~~~~^^^^^^^^^^^^^^^^^^^
  File "D:\BudgetTracker_Backend\.venv\Lib\site-packages\psycopg2\__init__.py", line 135, in connect
    conn = _connect(dsn, connection_factory=connection_factory, **kwasync)
psycopg2.OperationalError: connection to server at "localhost" (::1), port 5432 failed: FATAL:  database "budgettracker" does not exist


The above exception was the direct cause of the following exception:

Traceback (most recent call last):
  File "D:\BudgetTracker_Backend\routes\auth_routes.py", line 133, in login
    user = User.query.filter_by(email=email).first()
  File "D:\BudgetTracker_Backend\.venv\Lib\site-packages\sqlalchemy\orm\query.py", line 2759, in first
    return self.limit(1)._iter().first()  # type: ignore
           ~~~~~~~~~~~~~~~~~~~^^
  File "D:\BudgetTracker_Backend\.venv\Lib\site-packages\sqlalchemy\orm\query.py", line 2857, in _iter
    result: Union[ScalarResult[_T], Result[_T]] = self.session.execute(
                                                  ~~~~~~~~~~~~~~~~~~~~^
        statement,
        ^^^^^^^^^^
        params,
        ^^^^^^^
        execution_options={"_sa_orm_load_options": self.load_options},
        ^^^^^^^^^^^^^^^^^^^^^^^^^^^^^^^^^^^^^^^^^^^^^^^^^^^^^^^^^^^^^^
    )
    ^
  File "D:\BudgetTracker_Backend\.venv\Lib\site-packages\sqlalchemy\orm\session.py", line 2365, in execute
    return self._execute_internal(
           ~~~~~~~~~~~~~~~~~~~~~~^
        statement,
        ^^^^^^^^^^
    ...<4 lines>...
        _add_event=_add_event,
        ^^^^^^^^^^^^^^^^^^^^^^
    )
    ^
  File "D:\BudgetTracker_Backend\.venv\Lib\site-packages\sqlalchemy\orm\session.py", line 2241, in _execute_internal
    conn = self._connection_for_bind(bind)
  File "D:\BudgetTracker_Backend\.venv\Lib\site-packages\sqlalchemy\orm\session.py", line 2110, in _connection_for_bind
    return trans._connection_for_bind(engine, execution_options)
           ~~~~~~~~~~~~~~~~~~~~~~~~~~^^^^^^^^^^^^^^^^^^^^^^^^^^^
  File "<string>", line 2, in _connection_for_bind
  File "D:\BudgetTracker_Backend\.venv\Lib\site-packages\sqlalchemy\orm\state_changes.py", line 137, in _go
    ret_value = fn(self, *arg, **kw)
  File "D:\BudgetTracker_Backend\.venv\Lib\site-packages\sqlalchemy\orm\session.py", line 1189, in _connection_for_bind
    conn = bind.connect()
  File "D:\BudgetTracker_Backend\.venv\Lib\site-packages\sqlalchemy\engine\base.py", line 3277, in connect
    return self._connection_cls(self)
           ~~~~~~~~~~~~~~~~~~~~^^^^^^
  File "D:\BudgetTracker_Backend\.venv\Lib\site-packages\sqlalchemy\engine\base.py", line 145, in __init__
    Connection._handle_dbapi_exception_noconnection(
    ~~~~~~~~~~~~~~~~~~~~~~~~~~~~~~~~~~~~~~~~~~~~~~~^
        err, dialect, engine
        ^^^^^^^^^^^^^^^^^^^^
    )
    ^
  File "D:\BudgetTracker_Backend\.venv\Lib\site-packages\sqlalchemy\engine\base.py", line 2440, in _handle_dbapi_exception_noconnection
    raise sqlalchemy_exception.with_traceback(exc_info[2]) from e
  File "D:\BudgetTracker_Backend\.venv\Lib\site-packages\sqlalchemy\engine\base.py", line 143, in __init__
    self._dbapi_connection = engine.raw_connection()
                             ~~~~~~~~~~~~~~~~~~~~~^^
  File "D:\BudgetTracker_Backend\.venv\Lib\site-packages\sqlalchemy\engine\base.py", line 3301, in raw_connection
    return self.pool.connect()
           ~~~~~~~~~~~~~~~~~^^
  File "D:\BudgetTracker_Backend\.venv\Lib\site-packages\sqlalchemy\pool\base.py", line 447, in connect
    return _ConnectionFairy._checkout(self)
           ~~~~~~~~~~~~~~~~~~~~~~~~~~^^^^^^
  File "D:\BudgetTracker_Backend\.venv\Lib\site-packages\sqlalchemy\pool\base.py", line 1264, in _checkout
    fairy = _ConnectionRecord.checkout(pool)
  File "D:\BudgetTracker_Backend\.venv\Lib\site-packages\sqlalchemy\pool\base.py", line 711, in checkout
    rec = pool._do_get()
  File "D:\BudgetTracker_Backend\.venv\Lib\site-packages\sqlalchemy\pool\impl.py", line 177, in _do_get
    with util.safe_reraise():
         ~~~~~~~~~~~~~~~~~^^
  File "D:\BudgetTracker_Backend\.venv\Lib\site-packages\sqlalchemy\util\langhelpers.py", line 224, in __exit__
    raise exc_value.with_traceback(exc_tb)
  File "D:\BudgetTracker_Backend\.venv\Lib\site-packages\sqlalchemy\pool\impl.py", line 175, in _do_get
    return self._create_connection()
           ~~~~~~~~~~~~~~~~~~~~~~~^^
  File "D:\BudgetTracker_Backend\.venv\Lib\site-packages\sqlalchemy\pool\base.py", line 388, in _create_connection
    return _ConnectionRecord(self)
  File "D:\BudgetTracker_Backend\.venv\Lib\site-packages\sqlalchemy\pool\base.py", line 673, in __init__
    self.__connect()
    ~~~~~~~~~~~~~~^^
  File "D:\BudgetTracker_Backend\.venv\Lib\site-packages\sqlalchemy\pool\base.py", line 899, in __connect
    with util.safe_reraise():
         ~~~~~~~~~~~~~~~~~^^
  File "D:\BudgetTracker_Backend\.venv\Lib\site-packages\sqlalchemy\util\langhelpers.py", line 224, in __exit__
    raise exc_value.with_traceback(exc_tb)
  File "D:\BudgetTracker_Backend\.venv\Lib\site-packages\sqlalchemy\pool\base.py", line 895, in __connect
    self.dbapi_connection = connection = pool._invoke_creator(self)
                                         ~~~~~~~~~~~~~~~~~~~~^^^^^^
  File "D:\BudgetTracker_Backend\.venv\Lib\site-packages\sqlalchemy\engine\create.py", line 661, in connect
    return dialect.connect(*cargs, **cparams)
           ~~~~~~~~~~~~~~~^^^^^^^^^^^^^^^^^^^
  File "D:\BudgetTracker_Backend\.venv\Lib\site-packages\sqlalchemy\engine\default.py", line 629, in connect
    return self.loaded_dbapi.connect(*cargs, **cparams)  # type: ignore[no-any-return]  # NOQA: E501
           ~~~~~~~~~~~~~~~~~~~~~~~~~^^^^^^^^^^^^^^^^^^^
  File "D:\BudgetTracker_Backend\.venv\Lib\site-packages\psycopg2\__init__.py", line 135, in connect
    conn = _connect(dsn, connection_factory=connection_factory, **kwasync)
sqlalchemy.exc.OperationalError: (psycopg2.OperationalError) connection to server at "localhost" (::1), port 5432 failed: FATAL:  database "budgettracker" does not exist

(Background on this error at: https://sqlalche.me/e/20/e3q8)
2025-09-19 17:10:26,274 [ERROR] app: ❌ Error in /auth/login: (psycopg2.OperationalError) connection to server at "localhost" (::1), port 5432 failed: FATAL:  database "budgettracker" does not exist

(Background on this error at: https://sqlalche.me/e/20/e3q8)
Traceback (most recent call last):
  File "D:\BudgetTracker_Backend\.venv\Lib\site-packages\sqlalchemy\engine\base.py", line 143, in __init__
    self._dbapi_connection = engine.raw_connection()
                             ~~~~~~~~~~~~~~~~~~~~~^^
  File "D:\BudgetTracker_Backend\.venv\Lib\site-packages\sqlalchemy\engine\base.py", line 3301, in raw_connection
    return self.pool.connect()
           ~~~~~~~~~~~~~~~~~^^
  File "D:\BudgetTracker_Backend\.venv\Lib\site-packages\sqlalchemy\pool\base.py", line 447, in connect
    return _ConnectionFairy._checkout(self)
           ~~~~~~~~~~~~~~~~~~~~~~~~~~^^^^^^
  File "D:\BudgetTracker_Backend\.venv\Lib\site-packages\sqlalchemy\pool\base.py", line 1264, in _checkout
    fairy = _ConnectionRecord.checkout(pool)
  File "D:\BudgetTracker_Backend\.venv\Lib\site-packages\sqlalchemy\pool\base.py", line 711, in checkout
    rec = pool._do_get()
  File "D:\BudgetTracker_Backend\.venv\Lib\site-packages\sqlalchemy\pool\impl.py", line 177, in _do_get
    with util.safe_reraise():
         ~~~~~~~~~~~~~~~~~^^
  File "D:\BudgetTracker_Backend\.venv\Lib\site-packages\sqlalchemy\util\langhelpers.py", line 224, in __exit__
    raise exc_value.with_traceback(exc_tb)
  File "D:\BudgetTracker_Backend\.venv\Lib\site-packages\sqlalchemy\pool\impl.py", line 175, in _do_get
    return self._create_connection()
           ~~~~~~~~~~~~~~~~~~~~~~~^^
  File "D:\BudgetTracker_Backend\.venv\Lib\site-packages\sqlalchemy\pool\base.py", line 388, in _create_connection
    return _ConnectionRecord(self)
  File "D:\BudgetTracker_Backend\.venv\Lib\site-packages\sqlalchemy\pool\base.py", line 673, in __init__
    self.__connect()
    ~~~~~~~~~~~~~~^^
  File "D:\BudgetTracker_Backend\.venv\Lib\site-packages\sqlalchemy\pool\base.py", line 899, in __connect
    with util.safe_reraise():
         ~~~~~~~~~~~~~~~~~^^
  File "D:\BudgetTracker_Backend\.venv\Lib\site-packages\sqlalchemy\util\langhelpers.py", line 224, in __exit__
    raise exc_value.with_traceback(exc_tb)
  File "D:\BudgetTracker_Backend\.venv\Lib\site-packages\sqlalchemy\pool\base.py", line 895, in __connect
    self.dbapi_connection = connection = pool._invoke_creator(self)
                                         ~~~~~~~~~~~~~~~~~~~~^^^^^^
  File "D:\BudgetTracker_Backend\.venv\Lib\site-packages\sqlalchemy\engine\create.py", line 661, in connect
    return dialect.connect(*cargs, **cparams)
           ~~~~~~~~~~~~~~~^^^^^^^^^^^^^^^^^^^
  File "D:\BudgetTracker_Backend\.venv\Lib\site-packages\sqlalchemy\engine\default.py", line 629, in connect
    return self.loaded_dbapi.connect(*cargs, **cparams)  # type: ignore[no-any-return]  # NOQA: E501
           ~~~~~~~~~~~~~~~~~~~~~~~~~^^^^^^^^^^^^^^^^^^^
  File "D:\BudgetTracker_Backend\.venv\Lib\site-packages\psycopg2\__init__.py", line 135, in connect
    conn = _connect(dsn, connection_factory=connection_factory, **kwasync)
psycopg2.OperationalError: connection to server at "localhost" (::1), port 5432 failed: FATAL:  database "budgettracker" does not exist


The above exception was the direct cause of the following exception:

Traceback (most recent call last):
  File "D:\BudgetTracker_Backend\routes\auth_routes.py", line 133, in login
    user = User.query.filter_by(email=email).first()
  File "D:\BudgetTracker_Backend\.venv\Lib\site-packages\sqlalchemy\orm\query.py", line 2759, in first
    return self.limit(1)._iter().first()  # type: ignore
           ~~~~~~~~~~~~~~~~~~~^^
  File "D:\BudgetTracker_Backend\.venv\Lib\site-packages\sqlalchemy\orm\query.py", line 2857, in _iter
    result: Union[ScalarResult[_T], Result[_T]] = self.session.execute(
                                                  ~~~~~~~~~~~~~~~~~~~~^
        statement,
        ^^^^^^^^^^
        params,
        ^^^^^^^
        execution_options={"_sa_orm_load_options": self.load_options},
        ^^^^^^^^^^^^^^^^^^^^^^^^^^^^^^^^^^^^^^^^^^^^^^^^^^^^^^^^^^^^^^
    )
    ^
  File "D:\BudgetTracker_Backend\.venv\Lib\site-packages\sqlalchemy\orm\session.py", line 2365, in execute
    return self._execute_internal(
           ~~~~~~~~~~~~~~~~~~~~~~^
        statement,
        ^^^^^^^^^^
    ...<4 lines>...
        _add_event=_add_event,
        ^^^^^^^^^^^^^^^^^^^^^^
    )
    ^
  File "D:\BudgetTracker_Backend\.venv\Lib\site-packages\sqlalchemy\orm\session.py", line 2241, in _execute_internal
    conn = self._connection_for_bind(bind)
  File "D:\BudgetTracker_Backend\.venv\Lib\site-packages\sqlalchemy\orm\session.py", line 2110, in _connection_for_bind
    return trans._connection_for_bind(engine, execution_options)
           ~~~~~~~~~~~~~~~~~~~~~~~~~~^^^^^^^^^^^^^^^^^^^^^^^^^^^
  File "<string>", line 2, in _connection_for_bind
  File "D:\BudgetTracker_Backend\.venv\Lib\site-packages\sqlalchemy\orm\state_changes.py", line 137, in _go
    ret_value = fn(self, *arg, **kw)
  File "D:\BudgetTracker_Backend\.venv\Lib\site-packages\sqlalchemy\orm\session.py", line 1189, in _connection_for_bind
    conn = bind.connect()
  File "D:\BudgetTracker_Backend\.venv\Lib\site-packages\sqlalchemy\engine\base.py", line 3277, in connect
    return self._connection_cls(self)
           ~~~~~~~~~~~~~~~~~~~~^^^^^^
  File "D:\BudgetTracker_Backend\.venv\Lib\site-packages\sqlalchemy\engine\base.py", line 145, in __init__
    Connection._handle_dbapi_exception_noconnection(
    ~~~~~~~~~~~~~~~~~~~~~~~~~~~~~~~~~~~~~~~~~~~~~~~^
        err, dialect, engine
        ^^^^^^^^^^^^^^^^^^^^
    )
    ^
  File "D:\BudgetTracker_Backend\.venv\Lib\site-packages\sqlalchemy\engine\base.py", line 2440, in _handle_dbapi_exception_noconnection
    raise sqlalchemy_exception.with_traceback(exc_info[2]) from e
  File "D:\BudgetTracker_Backend\.venv\Lib\site-packages\sqlalchemy\engine\base.py", line 143, in __init__
    self._dbapi_connection = engine.raw_connection()
                             ~~~~~~~~~~~~~~~~~~~~~^^
  File "D:\BudgetTracker_Backend\.venv\Lib\site-packages\sqlalchemy\engine\base.py", line 3301, in raw_connection
    return self.pool.connect()
           ~~~~~~~~~~~~~~~~~^^
  File "D:\BudgetTracker_Backend\.venv\Lib\site-packages\sqlalchemy\pool\base.py", line 447, in connect
    return _ConnectionFairy._checkout(self)
           ~~~~~~~~~~~~~~~~~~~~~~~~~~^^^^^^
  File "D:\BudgetTracker_Backend\.venv\Lib\site-packages\sqlalchemy\pool\base.py", line 1264, in _checkout
    fairy = _ConnectionRecord.checkout(pool)
  File "D:\BudgetTracker_Backend\.venv\Lib\site-packages\sqlalchemy\pool\base.py", line 711, in checkout
    rec = pool._do_get()
  File "D:\BudgetTracker_Backend\.venv\Lib\site-packages\sqlalchemy\pool\impl.py", line 177, in _do_get
    with util.safe_reraise():
         ~~~~~~~~~~~~~~~~~^^
  File "D:\BudgetTracker_Backend\.venv\Lib\site-packages\sqlalchemy\util\langhelpers.py", line 224, in __exit__
    raise exc_value.with_traceback(exc_tb)
  File "D:\BudgetTracker_Backend\.venv\Lib\site-packages\sqlalchemy\pool\impl.py", line 175, in _do_get
    return self._create_connection()
           ~~~~~~~~~~~~~~~~~~~~~~~^^
  File "D:\BudgetTracker_Backend\.venv\Lib\site-packages\sqlalchemy\pool\base.py", line 388, in _create_connection
    return _ConnectionRecord(self)
  File "D:\BudgetTracker_Backend\.venv\Lib\site-packages\sqlalchemy\pool\base.py", line 673, in __init__
    self.__connect()
    ~~~~~~~~~~~~~~^^
  File "D:\BudgetTracker_Backend\.venv\Lib\site-packages\sqlalchemy\pool\base.py", line 899, in __connect
    with util.safe_reraise():
         ~~~~~~~~~~~~~~~~~^^
  File "D:\BudgetTracker_Backend\.venv\Lib\site-packages\sqlalchemy\util\langhelpers.py", line 224, in __exit__
    raise exc_value.with_traceback(exc_tb)
  File "D:\BudgetTracker_Backend\.venv\Lib\site-packages\sqlalchemy\pool\base.py", line 895, in __connect
    self.dbapi_connection = connection = pool._invoke_creator(self)
                                         ~~~~~~~~~~~~~~~~~~~~^^^^^^
  File "D:\BudgetTracker_Backend\.venv\Lib\site-packages\sqlalchemy\engine\create.py", line 661, in connect
    return dialect.connect(*cargs, **cparams)
           ~~~~~~~~~~~~~~~^^^^^^^^^^^^^^^^^^^
  File "D:\BudgetTracker_Backend\.venv\Lib\site-packages\sqlalchemy\engine\default.py", line 629, in connect
    return self.loaded_dbapi.connect(*cargs, **cparams)  # type: ignore[no-any-return]  # NOQA: E501
           ~~~~~~~~~~~~~~~~~~~~~~~~~^^^^^^^^^^^^^^^^^^^
  File "D:\BudgetTracker_Backend\.venv\Lib\site-packages\psycopg2\__init__.py", line 135, in connect
    conn = _connect(dsn, connection_factory=connection_factory, **kwasync)
sqlalchemy.exc.OperationalError: (psycopg2.OperationalError) connection to server at "localhost" (::1), port 5432 failed: FATAL:  database "budgettracker" does not exist

(Background on this error at: https://sqlalche.me/e/20/e3q8)
2025-09-19 17:10:27,723 [ERROR] app: ❌ Error in /auth/login: (psycopg2.OperationalError) connection to server at "localhost" (::1), port 5432 failed: FATAL:  database "budgettracker" does not exist

(Background on this error at: https://sqlalche.me/e/20/e3q8)
Traceback (most recent call last):
  File "D:\BudgetTracker_Backend\.venv\Lib\site-packages\sqlalchemy\engine\base.py", line 143, in __init__
    self._dbapi_connection = engine.raw_connection()
                             ~~~~~~~~~~~~~~~~~~~~~^^
  File "D:\BudgetTracker_Backend\.venv\Lib\site-packages\sqlalchemy\engine\base.py", line 3301, in raw_connection
    return self.pool.connect()
           ~~~~~~~~~~~~~~~~~^^
  File "D:\BudgetTracker_Backend\.venv\Lib\site-packages\sqlalchemy\pool\base.py", line 447, in connect
    return _ConnectionFairy._checkout(self)
           ~~~~~~~~~~~~~~~~~~~~~~~~~~^^^^^^
  File "D:\BudgetTracker_Backend\.venv\Lib\site-packages\sqlalchemy\pool\base.py", line 1264, in _checkout
    fairy = _ConnectionRecord.checkout(pool)
  File "D:\BudgetTracker_Backend\.venv\Lib\site-packages\sqlalchemy\pool\base.py", line 711, in checkout
    rec = pool._do_get()
  File "D:\BudgetTracker_Backend\.venv\Lib\site-packages\sqlalchemy\pool\impl.py", line 177, in _do_get
    with util.safe_reraise():
         ~~~~~~~~~~~~~~~~~^^
  File "D:\BudgetTracker_Backend\.venv\Lib\site-packages\sqlalchemy\util\langhelpers.py", line 224, in __exit__
    raise exc_value.with_traceback(exc_tb)
  File "D:\BudgetTracker_Backend\.venv\Lib\site-packages\sqlalchemy\pool\impl.py", line 175, in _do_get
    return self._create_connection()
           ~~~~~~~~~~~~~~~~~~~~~~~^^
  File "D:\BudgetTracker_Backend\.venv\Lib\site-packages\sqlalchemy\pool\base.py", line 388, in _create_connection
    return _ConnectionRecord(self)
  File "D:\BudgetTracker_Backend\.venv\Lib\site-packages\sqlalchemy\pool\base.py", line 673, in __init__
    self.__connect()
    ~~~~~~~~~~~~~~^^
  File "D:\BudgetTracker_Backend\.venv\Lib\site-packages\sqlalchemy\pool\base.py", line 899, in __connect
    with util.safe_reraise():
         ~~~~~~~~~~~~~~~~~^^
  File "D:\BudgetTracker_Backend\.venv\Lib\site-packages\sqlalchemy\util\langhelpers.py", line 224, in __exit__
    raise exc_value.with_traceback(exc_tb)
  File "D:\BudgetTracker_Backend\.venv\Lib\site-packages\sqlalchemy\pool\base.py", line 895, in __connect
    self.dbapi_connection = connection = pool._invoke_creator(self)
                                         ~~~~~~~~~~~~~~~~~~~~^^^^^^
  File "D:\BudgetTracker_Backend\.venv\Lib\site-packages\sqlalchemy\engine\create.py", line 661, in connect
    return dialect.connect(*cargs, **cparams)
           ~~~~~~~~~~~~~~~^^^^^^^^^^^^^^^^^^^
  File "D:\BudgetTracker_Backend\.venv\Lib\site-packages\sqlalchemy\engine\default.py", line 629, in connect
    return self.loaded_dbapi.connect(*cargs, **cparams)  # type: ignore[no-any-return]  # NOQA: E501
           ~~~~~~~~~~~~~~~~~~~~~~~~~^^^^^^^^^^^^^^^^^^^
  File "D:\BudgetTracker_Backend\.venv\Lib\site-packages\psycopg2\__init__.py", line 135, in connect
    conn = _connect(dsn, connection_factory=connection_factory, **kwasync)
psycopg2.OperationalError: connection to server at "localhost" (::1), port 5432 failed: FATAL:  database "budgettracker" does not exist


The above exception was the direct cause of the following exception:

Traceback (most recent call last):
  File "D:\BudgetTracker_Backend\routes\auth_routes.py", line 133, in login
    user = User.query.filter_by(email=email).first()
  File "D:\BudgetTracker_Backend\.venv\Lib\site-packages\sqlalchemy\orm\query.py", line 2759, in first
    return self.limit(1)._iter().first()  # type: ignore
           ~~~~~~~~~~~~~~~~~~~^^
  File "D:\BudgetTracker_Backend\.venv\Lib\site-packages\sqlalchemy\orm\query.py", line 2857, in _iter
    result: Union[ScalarResult[_T], Result[_T]] = self.session.execute(
                                                  ~~~~~~~~~~~~~~~~~~~~^
        statement,
        ^^^^^^^^^^
        params,
        ^^^^^^^
        execution_options={"_sa_orm_load_options": self.load_options},
        ^^^^^^^^^^^^^^^^^^^^^^^^^^^^^^^^^^^^^^^^^^^^^^^^^^^^^^^^^^^^^^
    )
    ^
  File "D:\BudgetTracker_Backend\.venv\Lib\site-packages\sqlalchemy\orm\session.py", line 2365, in execute
    return self._execute_internal(
           ~~~~~~~~~~~~~~~~~~~~~~^
        statement,
        ^^^^^^^^^^
    ...<4 lines>...
        _add_event=_add_event,
        ^^^^^^^^^^^^^^^^^^^^^^
    )
    ^
  File "D:\BudgetTracker_Backend\.venv\Lib\site-packages\sqlalchemy\orm\session.py", line 2241, in _execute_internal
    conn = self._connection_for_bind(bind)
  File "D:\BudgetTracker_Backend\.venv\Lib\site-packages\sqlalchemy\orm\session.py", line 2110, in _connection_for_bind
    return trans._connection_for_bind(engine, execution_options)
           ~~~~~~~~~~~~~~~~~~~~~~~~~~^^^^^^^^^^^^^^^^^^^^^^^^^^^
  File "<string>", line 2, in _connection_for_bind
  File "D:\BudgetTracker_Backend\.venv\Lib\site-packages\sqlalchemy\orm\state_changes.py", line 137, in _go
    ret_value = fn(self, *arg, **kw)
  File "D:\BudgetTracker_Backend\.venv\Lib\site-packages\sqlalchemy\orm\session.py", line 1189, in _connection_for_bind
    conn = bind.connect()
  File "D:\BudgetTracker_Backend\.venv\Lib\site-packages\sqlalchemy\engine\base.py", line 3277, in connect
    return self._connection_cls(self)
           ~~~~~~~~~~~~~~~~~~~~^^^^^^
  File "D:\BudgetTracker_Backend\.venv\Lib\site-packages\sqlalchemy\engine\base.py", line 145, in __init__
    Connection._handle_dbapi_exception_noconnection(
    ~~~~~~~~~~~~~~~~~~~~~~~~~~~~~~~~~~~~~~~~~~~~~~~^
        err, dialect, engine
        ^^^^^^^^^^^^^^^^^^^^
    )
    ^
  File "D:\BudgetTracker_Backend\.venv\Lib\site-packages\sqlalchemy\engine\base.py", line 2440, in _handle_dbapi_exception_noconnection
    raise sqlalchemy_exception.with_traceback(exc_info[2]) from e
  File "D:\BudgetTracker_Backend\.venv\Lib\site-packages\sqlalchemy\engine\base.py", line 143, in __init__
    self._dbapi_connection = engine.raw_connection()
                             ~~~~~~~~~~~~~~~~~~~~~^^
  File "D:\BudgetTracker_Backend\.venv\Lib\site-packages\sqlalchemy\engine\base.py", line 3301, in raw_connection
    return self.pool.connect()
           ~~~~~~~~~~~~~~~~~^^
  File "D:\BudgetTracker_Backend\.venv\Lib\site-packages\sqlalchemy\pool\base.py", line 447, in connect
    return _ConnectionFairy._checkout(self)
           ~~~~~~~~~~~~~~~~~~~~~~~~~~^^^^^^
  File "D:\BudgetTracker_Backend\.venv\Lib\site-packages\sqlalchemy\pool\base.py", line 1264, in _checkout
    fairy = _ConnectionRecord.checkout(pool)
  File "D:\BudgetTracker_Backend\.venv\Lib\site-packages\sqlalchemy\pool\base.py", line 711, in checkout
    rec = pool._do_get()
  File "D:\BudgetTracker_Backend\.venv\Lib\site-packages\sqlalchemy\pool\impl.py", line 177, in _do_get
    with util.safe_reraise():
         ~~~~~~~~~~~~~~~~~^^
  File "D:\BudgetTracker_Backend\.venv\Lib\site-packages\sqlalchemy\util\langhelpers.py", line 224, in __exit__
    raise exc_value.with_traceback(exc_tb)
  File "D:\BudgetTracker_Backend\.venv\Lib\site-packages\sqlalchemy\pool\impl.py", line 175, in _do_get
    return self._create_connection()
           ~~~~~~~~~~~~~~~~~~~~~~~^^
  File "D:\BudgetTracker_Backend\.venv\Lib\site-packages\sqlalchemy\pool\base.py", line 388, in _create_connection
    return _ConnectionRecord(self)
  File "D:\BudgetTracker_Backend\.venv\Lib\site-packages\sqlalchemy\pool\base.py", line 673, in __init__
    self.__connect()
    ~~~~~~~~~~~~~~^^
  File "D:\BudgetTracker_Backend\.venv\Lib\site-packages\sqlalchemy\pool\base.py", line 899, in __connect
    with util.safe_reraise():
         ~~~~~~~~~~~~~~~~~^^
  File "D:\BudgetTracker_Backend\.venv\Lib\site-packages\sqlalchemy\util\langhelpers.py", line 224, in __exit__
    raise exc_value.with_traceback(exc_tb)
  File "D:\BudgetTracker_Backend\.venv\Lib\site-packages\sqlalchemy\pool\base.py", line 895, in __connect
    self.dbapi_connection = connection = pool._invoke_creator(self)
                                         ~~~~~~~~~~~~~~~~~~~~^^^^^^
  File "D:\BudgetTracker_Backend\.venv\Lib\site-packages\sqlalchemy\engine\create.py", line 661, in connect
    return dialect.connect(*cargs, **cparams)
           ~~~~~~~~~~~~~~~^^^^^^^^^^^^^^^^^^^
  File "D:\BudgetTracker_Backend\.venv\Lib\site-packages\sqlalchemy\engine\default.py", line 629, in connect
    return self.loaded_dbapi.connect(*cargs, **cparams)  # type: ignore[no-any-return]  # NOQA: E501
           ~~~~~~~~~~~~~~~~~~~~~~~~~^^^^^^^^^^^^^^^^^^^
  File "D:\BudgetTracker_Backend\.venv\Lib\site-packages\psycopg2\__init__.py", line 135, in connect
    conn = _connect(dsn, connection_factory=connection_factory, **kwasync)
sqlalchemy.exc.OperationalError: (psycopg2.OperationalError) connection to server at "localhost" (::1), port 5432 failed: FATAL:  database "budgettracker" does not exist

(Background on this error at: https://sqlalche.me/e/20/e3q8)
2025-09-19 17:13:14,465 [ERROR] app: ❌ Error in /auth/login: (psycopg2.OperationalError) connection to server at "localhost" (::1), port 5432 failed: FATAL:  database "budgettracker" does not exist

(Background on this error at: https://sqlalche.me/e/20/e3q8)
Traceback (most recent call last):
  File "D:\BudgetTracker_Backend\.venv\Lib\site-packages\sqlalchemy\engine\base.py", line 143, in __init__
    self._dbapi_connection = engine.raw_connection()
                             ~~~~~~~~~~~~~~~~~~~~~^^
  File "D:\BudgetTracker_Backend\.venv\Lib\site-packages\sqlalchemy\engine\base.py", line 3301, in raw_connection
    return self.pool.connect()
           ~~~~~~~~~~~~~~~~~^^
  File "D:\BudgetTracker_Backend\.venv\Lib\site-packages\sqlalchemy\pool\base.py", line 447, in connect
    return _ConnectionFairy._checkout(self)
           ~~~~~~~~~~~~~~~~~~~~~~~~~~^^^^^^
  File "D:\BudgetTracker_Backend\.venv\Lib\site-packages\sqlalchemy\pool\base.py", line 1264, in _checkout
    fairy = _ConnectionRecord.checkout(pool)
  File "D:\BudgetTracker_Backend\.venv\Lib\site-packages\sqlalchemy\pool\base.py", line 711, in checkout
    rec = pool._do_get()
  File "D:\BudgetTracker_Backend\.venv\Lib\site-packages\sqlalchemy\pool\impl.py", line 177, in _do_get
    with util.safe_reraise():
         ~~~~~~~~~~~~~~~~~^^
  File "D:\BudgetTracker_Backend\.venv\Lib\site-packages\sqlalchemy\util\langhelpers.py", line 224, in __exit__
    raise exc_value.with_traceback(exc_tb)
  File "D:\BudgetTracker_Backend\.venv\Lib\site-packages\sqlalchemy\pool\impl.py", line 175, in _do_get
    return self._create_connection()
           ~~~~~~~~~~~~~~~~~~~~~~~^^
  File "D:\BudgetTracker_Backend\.venv\Lib\site-packages\sqlalchemy\pool\base.py", line 388, in _create_connection
    return _ConnectionRecord(self)
  File "D:\BudgetTracker_Backend\.venv\Lib\site-packages\sqlalchemy\pool\base.py", line 673, in __init__
    self.__connect()
    ~~~~~~~~~~~~~~^^
  File "D:\BudgetTracker_Backend\.venv\Lib\site-packages\sqlalchemy\pool\base.py", line 899, in __connect
    with util.safe_reraise():
         ~~~~~~~~~~~~~~~~~^^
  File "D:\BudgetTracker_Backend\.venv\Lib\site-packages\sqlalchemy\util\langhelpers.py", line 224, in __exit__
    raise exc_value.with_traceback(exc_tb)
  File "D:\BudgetTracker_Backend\.venv\Lib\site-packages\sqlalchemy\pool\base.py", line 895, in __connect
    self.dbapi_connection = connection = pool._invoke_creator(self)
                                         ~~~~~~~~~~~~~~~~~~~~^^^^^^
  File "D:\BudgetTracker_Backend\.venv\Lib\site-packages\sqlalchemy\engine\create.py", line 661, in connect
    return dialect.connect(*cargs, **cparams)
           ~~~~~~~~~~~~~~~^^^^^^^^^^^^^^^^^^^
  File "D:\BudgetTracker_Backend\.venv\Lib\site-packages\sqlalchemy\engine\default.py", line 629, in connect
    return self.loaded_dbapi.connect(*cargs, **cparams)  # type: ignore[no-any-return]  # NOQA: E501
           ~~~~~~~~~~~~~~~~~~~~~~~~~^^^^^^^^^^^^^^^^^^^
  File "D:\BudgetTracker_Backend\.venv\Lib\site-packages\psycopg2\__init__.py", line 135, in connect
    conn = _connect(dsn, connection_factory=connection_factory, **kwasync)
psycopg2.OperationalError: connection to server at "localhost" (::1), port 5432 failed: FATAL:  database "budgettracker" does not exist


The above exception was the direct cause of the following exception:

Traceback (most recent call last):
  File "D:\BudgetTracker_Backend\routes\auth_routes.py", line 133, in login
    user = User.query.filter_by(email=email).first()
  File "D:\BudgetTracker_Backend\.venv\Lib\site-packages\sqlalchemy\orm\query.py", line 2759, in first
    return self.limit(1)._iter().first()  # type: ignore
           ~~~~~~~~~~~~~~~~~~~^^
  File "D:\BudgetTracker_Backend\.venv\Lib\site-packages\sqlalchemy\orm\query.py", line 2857, in _iter
    result: Union[ScalarResult[_T], Result[_T]] = self.session.execute(
                                                  ~~~~~~~~~~~~~~~~~~~~^
        statement,
        ^^^^^^^^^^
        params,
        ^^^^^^^
        execution_options={"_sa_orm_load_options": self.load_options},
        ^^^^^^^^^^^^^^^^^^^^^^^^^^^^^^^^^^^^^^^^^^^^^^^^^^^^^^^^^^^^^^
    )
    ^
  File "D:\BudgetTracker_Backend\.venv\Lib\site-packages\sqlalchemy\orm\session.py", line 2365, in execute
    return self._execute_internal(
           ~~~~~~~~~~~~~~~~~~~~~~^
        statement,
        ^^^^^^^^^^
    ...<4 lines>...
        _add_event=_add_event,
        ^^^^^^^^^^^^^^^^^^^^^^
    )
    ^
  File "D:\BudgetTracker_Backend\.venv\Lib\site-packages\sqlalchemy\orm\session.py", line 2241, in _execute_internal
    conn = self._connection_for_bind(bind)
  File "D:\BudgetTracker_Backend\.venv\Lib\site-packages\sqlalchemy\orm\session.py", line 2110, in _connection_for_bind
    return trans._connection_for_bind(engine, execution_options)
           ~~~~~~~~~~~~~~~~~~~~~~~~~~^^^^^^^^^^^^^^^^^^^^^^^^^^^
  File "<string>", line 2, in _connection_for_bind
  File "D:\BudgetTracker_Backend\.venv\Lib\site-packages\sqlalchemy\orm\state_changes.py", line 137, in _go
    ret_value = fn(self, *arg, **kw)
  File "D:\BudgetTracker_Backend\.venv\Lib\site-packages\sqlalchemy\orm\session.py", line 1189, in _connection_for_bind
    conn = bind.connect()
  File "D:\BudgetTracker_Backend\.venv\Lib\site-packages\sqlalchemy\engine\base.py", line 3277, in connect
    return self._connection_cls(self)
           ~~~~~~~~~~~~~~~~~~~~^^^^^^
  File "D:\BudgetTracker_Backend\.venv\Lib\site-packages\sqlalchemy\engine\base.py", line 145, in __init__
    Connection._handle_dbapi_exception_noconnection(
    ~~~~~~~~~~~~~~~~~~~~~~~~~~~~~~~~~~~~~~~~~~~~~~~^
        err, dialect, engine
        ^^^^^^^^^^^^^^^^^^^^
    )
    ^
  File "D:\BudgetTracker_Backend\.venv\Lib\site-packages\sqlalchemy\engine\base.py", line 2440, in _handle_dbapi_exception_noconnection
    raise sqlalchemy_exception.with_traceback(exc_info[2]) from e
  File "D:\BudgetTracker_Backend\.venv\Lib\site-packages\sqlalchemy\engine\base.py", line 143, in __init__
    self._dbapi_connection = engine.raw_connection()
                             ~~~~~~~~~~~~~~~~~~~~~^^
  File "D:\BudgetTracker_Backend\.venv\Lib\site-packages\sqlalchemy\engine\base.py", line 3301, in raw_connection
    return self.pool.connect()
           ~~~~~~~~~~~~~~~~~^^
  File "D:\BudgetTracker_Backend\.venv\Lib\site-packages\sqlalchemy\pool\base.py", line 447, in connect
    return _ConnectionFairy._checkout(self)
           ~~~~~~~~~~~~~~~~~~~~~~~~~~^^^^^^
  File "D:\BudgetTracker_Backend\.venv\Lib\site-packages\sqlalchemy\pool\base.py", line 1264, in _checkout
    fairy = _ConnectionRecord.checkout(pool)
  File "D:\BudgetTracker_Backend\.venv\Lib\site-packages\sqlalchemy\pool\base.py", line 711, in checkout
    rec = pool._do_get()
  File "D:\BudgetTracker_Backend\.venv\Lib\site-packages\sqlalchemy\pool\impl.py", line 177, in _do_get
    with util.safe_reraise():
         ~~~~~~~~~~~~~~~~~^^
  File "D:\BudgetTracker_Backend\.venv\Lib\site-packages\sqlalchemy\util\langhelpers.py", line 224, in __exit__
    raise exc_value.with_traceback(exc_tb)
  File "D:\BudgetTracker_Backend\.venv\Lib\site-packages\sqlalchemy\pool\impl.py", line 175, in _do_get
    return self._create_connection()
           ~~~~~~~~~~~~~~~~~~~~~~~^^
  File "D:\BudgetTracker_Backend\.venv\Lib\site-packages\sqlalchemy\pool\base.py", line 388, in _create_connection
    return _ConnectionRecord(self)
  File "D:\BudgetTracker_Backend\.venv\Lib\site-packages\sqlalchemy\pool\base.py", line 673, in __init__
    self.__connect()
    ~~~~~~~~~~~~~~^^
  File "D:\BudgetTracker_Backend\.venv\Lib\site-packages\sqlalchemy\pool\base.py", line 899, in __connect
    with util.safe_reraise():
         ~~~~~~~~~~~~~~~~~^^
  File "D:\BudgetTracker_Backend\.venv\Lib\site-packages\sqlalchemy\util\langhelpers.py", line 224, in __exit__
    raise exc_value.with_traceback(exc_tb)
  File "D:\BudgetTracker_Backend\.venv\Lib\site-packages\sqlalchemy\pool\base.py", line 895, in __connect
    self.dbapi_connection = connection = pool._invoke_creator(self)
                                         ~~~~~~~~~~~~~~~~~~~~^^^^^^
  File "D:\BudgetTracker_Backend\.venv\Lib\site-packages\sqlalchemy\engine\create.py", line 661, in connect
    return dialect.connect(*cargs, **cparams)
           ~~~~~~~~~~~~~~~^^^^^^^^^^^^^^^^^^^
  File "D:\BudgetTracker_Backend\.venv\Lib\site-packages\sqlalchemy\engine\default.py", line 629, in connect
    return self.loaded_dbapi.connect(*cargs, **cparams)  # type: ignore[no-any-return]  # NOQA: E501
           ~~~~~~~~~~~~~~~~~~~~~~~~~^^^^^^^^^^^^^^^^^^^
  File "D:\BudgetTracker_Backend\.venv\Lib\site-packages\psycopg2\__init__.py", line 135, in connect
    conn = _connect(dsn, connection_factory=connection_factory, **kwasync)
sqlalchemy.exc.OperationalError: (psycopg2.OperationalError) connection to server at "localhost" (::1), port 5432 failed: FATAL:  database "budgettracker" does not exist

(Background on this error at: https://sqlalche.me/e/20/e3q8)
2025-09-19 17:14:03,331 [ERROR] app: ❌ Error in /auth/login: (psycopg2.OperationalError) connection to server at "localhost" (::1), port 5432 failed: FATAL:  database "budgettracker" does not exist

(Background on this error at: https://sqlalche.me/e/20/e3q8)
Traceback (most recent call last):
  File "D:\BudgetTracker_Backend\.venv\Lib\site-packages\sqlalchemy\engine\base.py", line 143, in __init__
    self._dbapi_connection = engine.raw_connection()
                             ~~~~~~~~~~~~~~~~~~~~~^^
  File "D:\BudgetTracker_Backend\.venv\Lib\site-packages\sqlalchemy\engine\base.py", line 3301, in raw_connection
    return self.pool.connect()
           ~~~~~~~~~~~~~~~~~^^
  File "D:\BudgetTracker_Backend\.venv\Lib\site-packages\sqlalchemy\pool\base.py", line 447, in connect
    return _ConnectionFairy._checkout(self)
           ~~~~~~~~~~~~~~~~~~~~~~~~~~^^^^^^
  File "D:\BudgetTracker_Backend\.venv\Lib\site-packages\sqlalchemy\pool\base.py", line 1264, in _checkout
    fairy = _ConnectionRecord.checkout(pool)
  File "D:\BudgetTracker_Backend\.venv\Lib\site-packages\sqlalchemy\pool\base.py", line 711, in checkout
    rec = pool._do_get()
  File "D:\BudgetTracker_Backend\.venv\Lib\site-packages\sqlalchemy\pool\impl.py", line 177, in _do_get
    with util.safe_reraise():
         ~~~~~~~~~~~~~~~~~^^
  File "D:\BudgetTracker_Backend\.venv\Lib\site-packages\sqlalchemy\util\langhelpers.py", line 224, in __exit__
    raise exc_value.with_traceback(exc_tb)
  File "D:\BudgetTracker_Backend\.venv\Lib\site-packages\sqlalchemy\pool\impl.py", line 175, in _do_get
    return self._create_connection()
           ~~~~~~~~~~~~~~~~~~~~~~~^^
  File "D:\BudgetTracker_Backend\.venv\Lib\site-packages\sqlalchemy\pool\base.py", line 388, in _create_connection
    return _ConnectionRecord(self)
  File "D:\BudgetTracker_Backend\.venv\Lib\site-packages\sqlalchemy\pool\base.py", line 673, in __init__
    self.__connect()
    ~~~~~~~~~~~~~~^^
  File "D:\BudgetTracker_Backend\.venv\Lib\site-packages\sqlalchemy\pool\base.py", line 899, in __connect
    with util.safe_reraise():
         ~~~~~~~~~~~~~~~~~^^
  File "D:\BudgetTracker_Backend\.venv\Lib\site-packages\sqlalchemy\util\langhelpers.py", line 224, in __exit__
    raise exc_value.with_traceback(exc_tb)
  File "D:\BudgetTracker_Backend\.venv\Lib\site-packages\sqlalchemy\pool\base.py", line 895, in __connect
    self.dbapi_connection = connection = pool._invoke_creator(self)
                                         ~~~~~~~~~~~~~~~~~~~~^^^^^^
  File "D:\BudgetTracker_Backend\.venv\Lib\site-packages\sqlalchemy\engine\create.py", line 661, in connect
    return dialect.connect(*cargs, **cparams)
           ~~~~~~~~~~~~~~~^^^^^^^^^^^^^^^^^^^
  File "D:\BudgetTracker_Backend\.venv\Lib\site-packages\sqlalchemy\engine\default.py", line 629, in connect
    return self.loaded_dbapi.connect(*cargs, **cparams)  # type: ignore[no-any-return]  # NOQA: E501
           ~~~~~~~~~~~~~~~~~~~~~~~~~^^^^^^^^^^^^^^^^^^^
  File "D:\BudgetTracker_Backend\.venv\Lib\site-packages\psycopg2\__init__.py", line 135, in connect
    conn = _connect(dsn, connection_factory=connection_factory, **kwasync)
psycopg2.OperationalError: connection to server at "localhost" (::1), port 5432 failed: FATAL:  database "budgettracker" does not exist


The above exception was the direct cause of the following exception:

Traceback (most recent call last):
  File "D:\BudgetTracker_Backend\routes\auth_routes.py", line 133, in login
    user = User.query.filter_by(email=email).first()
  File "D:\BudgetTracker_Backend\.venv\Lib\site-packages\sqlalchemy\orm\query.py", line 2759, in first
    return self.limit(1)._iter().first()  # type: ignore
           ~~~~~~~~~~~~~~~~~~~^^
  File "D:\BudgetTracker_Backend\.venv\Lib\site-packages\sqlalchemy\orm\query.py", line 2857, in _iter
    result: Union[ScalarResult[_T], Result[_T]] = self.session.execute(
                                                  ~~~~~~~~~~~~~~~~~~~~^
        statement,
        ^^^^^^^^^^
        params,
        ^^^^^^^
        execution_options={"_sa_orm_load_options": self.load_options},
        ^^^^^^^^^^^^^^^^^^^^^^^^^^^^^^^^^^^^^^^^^^^^^^^^^^^^^^^^^^^^^^
    )
    ^
  File "D:\BudgetTracker_Backend\.venv\Lib\site-packages\sqlalchemy\orm\session.py", line 2365, in execute
    return self._execute_internal(
           ~~~~~~~~~~~~~~~~~~~~~~^
        statement,
        ^^^^^^^^^^
    ...<4 lines>...
        _add_event=_add_event,
        ^^^^^^^^^^^^^^^^^^^^^^
    )
    ^
  File "D:\BudgetTracker_Backend\.venv\Lib\site-packages\sqlalchemy\orm\session.py", line 2241, in _execute_internal
    conn = self._connection_for_bind(bind)
  File "D:\BudgetTracker_Backend\.venv\Lib\site-packages\sqlalchemy\orm\session.py", line 2110, in _connection_for_bind
    return trans._connection_for_bind(engine, execution_options)
           ~~~~~~~~~~~~~~~~~~~~~~~~~~^^^^^^^^^^^^^^^^^^^^^^^^^^^
  File "<string>", line 2, in _connection_for_bind
  File "D:\BudgetTracker_Backend\.venv\Lib\site-packages\sqlalchemy\orm\state_changes.py", line 137, in _go
    ret_value = fn(self, *arg, **kw)
  File "D:\BudgetTracker_Backend\.venv\Lib\site-packages\sqlalchemy\orm\session.py", line 1189, in _connection_for_bind
    conn = bind.connect()
  File "D:\BudgetTracker_Backend\.venv\Lib\site-packages\sqlalchemy\engine\base.py", line 3277, in connect
    return self._connection_cls(self)
           ~~~~~~~~~~~~~~~~~~~~^^^^^^
  File "D:\BudgetTracker_Backend\.venv\Lib\site-packages\sqlalchemy\engine\base.py", line 145, in __init__
    Connection._handle_dbapi_exception_noconnection(
    ~~~~~~~~~~~~~~~~~~~~~~~~~~~~~~~~~~~~~~~~~~~~~~~^
        err, dialect, engine
        ^^^^^^^^^^^^^^^^^^^^
    )
    ^
  File "D:\BudgetTracker_Backend\.venv\Lib\site-packages\sqlalchemy\engine\base.py", line 2440, in _handle_dbapi_exception_noconnection
    raise sqlalchemy_exception.with_traceback(exc_info[2]) from e
  File "D:\BudgetTracker_Backend\.venv\Lib\site-packages\sqlalchemy\engine\base.py", line 143, in __init__
    self._dbapi_connection = engine.raw_connection()
                             ~~~~~~~~~~~~~~~~~~~~~^^
  File "D:\BudgetTracker_Backend\.venv\Lib\site-packages\sqlalchemy\engine\base.py", line 3301, in raw_connection
    return self.pool.connect()
           ~~~~~~~~~~~~~~~~~^^
  File "D:\BudgetTracker_Backend\.venv\Lib\site-packages\sqlalchemy\pool\base.py", line 447, in connect
    return _ConnectionFairy._checkout(self)
           ~~~~~~~~~~~~~~~~~~~~~~~~~~^^^^^^
  File "D:\BudgetTracker_Backend\.venv\Lib\site-packages\sqlalchemy\pool\base.py", line 1264, in _checkout
    fairy = _ConnectionRecord.checkout(pool)
  File "D:\BudgetTracker_Backend\.venv\Lib\site-packages\sqlalchemy\pool\base.py", line 711, in checkout
    rec = pool._do_get()
  File "D:\BudgetTracker_Backend\.venv\Lib\site-packages\sqlalchemy\pool\impl.py", line 177, in _do_get
    with util.safe_reraise():
         ~~~~~~~~~~~~~~~~~^^
  File "D:\BudgetTracker_Backend\.venv\Lib\site-packages\sqlalchemy\util\langhelpers.py", line 224, in __exit__
    raise exc_value.with_traceback(exc_tb)
  File "D:\BudgetTracker_Backend\.venv\Lib\site-packages\sqlalchemy\pool\impl.py", line 175, in _do_get
    return self._create_connection()
           ~~~~~~~~~~~~~~~~~~~~~~~^^
  File "D:\BudgetTracker_Backend\.venv\Lib\site-packages\sqlalchemy\pool\base.py", line 388, in _create_connection
    return _ConnectionRecord(self)
  File "D:\BudgetTracker_Backend\.venv\Lib\site-packages\sqlalchemy\pool\base.py", line 673, in __init__
    self.__connect()
    ~~~~~~~~~~~~~~^^
  File "D:\BudgetTracker_Backend\.venv\Lib\site-packages\sqlalchemy\pool\base.py", line 899, in __connect
    with util.safe_reraise():
         ~~~~~~~~~~~~~~~~~^^
  File "D:\BudgetTracker_Backend\.venv\Lib\site-packages\sqlalchemy\util\langhelpers.py", line 224, in __exit__
    raise exc_value.with_traceback(exc_tb)
  File "D:\BudgetTracker_Backend\.venv\Lib\site-packages\sqlalchemy\pool\base.py", line 895, in __connect
    self.dbapi_connection = connection = pool._invoke_creator(self)
                                         ~~~~~~~~~~~~~~~~~~~~^^^^^^
  File "D:\BudgetTracker_Backend\.venv\Lib\site-packages\sqlalchemy\engine\create.py", line 661, in connect
    return dialect.connect(*cargs, **cparams)
           ~~~~~~~~~~~~~~~^^^^^^^^^^^^^^^^^^^
  File "D:\BudgetTracker_Backend\.venv\Lib\site-packages\sqlalchemy\engine\default.py", line 629, in connect
    return self.loaded_dbapi.connect(*cargs, **cparams)  # type: ignore[no-any-return]  # NOQA: E501
           ~~~~~~~~~~~~~~~~~~~~~~~~~^^^^^^^^^^^^^^^^^^^
  File "D:\BudgetTracker_Backend\.venv\Lib\site-packages\psycopg2\__init__.py", line 135, in connect
    conn = _connect(dsn, connection_factory=connection_factory, **kwasync)
sqlalchemy.exc.OperationalError: (psycopg2.OperationalError) connection to server at "localhost" (::1), port 5432 failed: FATAL:  database "budgettracker" does not exist

(Background on this error at: https://sqlalche.me/e/20/e3q8)
2025-09-19 17:21:54,754 [ERROR] app: ❌ Error in /auth/login: (psycopg2.OperationalError) connection to server at "localhost" (::1), port 5432 failed: FATAL:  database "budgettracker" does not exist

(Background on this error at: https://sqlalche.me/e/20/e3q8)
Traceback (most recent call last):
  File "D:\BudgetTracker_Backend\.venv\Lib\site-packages\sqlalchemy\engine\base.py", line 143, in __init__
    self._dbapi_connection = engine.raw_connection()
                             ~~~~~~~~~~~~~~~~~~~~~^^
  File "D:\BudgetTracker_Backend\.venv\Lib\site-packages\sqlalchemy\engine\base.py", line 3301, in raw_connection
    return self.pool.connect()
           ~~~~~~~~~~~~~~~~~^^
  File "D:\BudgetTracker_Backend\.venv\Lib\site-packages\sqlalchemy\pool\base.py", line 447, in connect
    return _ConnectionFairy._checkout(self)
           ~~~~~~~~~~~~~~~~~~~~~~~~~~^^^^^^
  File "D:\BudgetTracker_Backend\.venv\Lib\site-packages\sqlalchemy\pool\base.py", line 1264, in _checkout
    fairy = _ConnectionRecord.checkout(pool)
  File "D:\BudgetTracker_Backend\.venv\Lib\site-packages\sqlalchemy\pool\base.py", line 711, in checkout
    rec = pool._do_get()
  File "D:\BudgetTracker_Backend\.venv\Lib\site-packages\sqlalchemy\pool\impl.py", line 177, in _do_get
    with util.safe_reraise():
         ~~~~~~~~~~~~~~~~~^^
  File "D:\BudgetTracker_Backend\.venv\Lib\site-packages\sqlalchemy\util\langhelpers.py", line 224, in __exit__
    raise exc_value.with_traceback(exc_tb)
  File "D:\BudgetTracker_Backend\.venv\Lib\site-packages\sqlalchemy\pool\impl.py", line 175, in _do_get
    return self._create_connection()
           ~~~~~~~~~~~~~~~~~~~~~~~^^
  File "D:\BudgetTracker_Backend\.venv\Lib\site-packages\sqlalchemy\pool\base.py", line 388, in _create_connection
    return _ConnectionRecord(self)
  File "D:\BudgetTracker_Backend\.venv\Lib\site-packages\sqlalchemy\pool\base.py", line 673, in __init__
    self.__connect()
    ~~~~~~~~~~~~~~^^
  File "D:\BudgetTracker_Backend\.venv\Lib\site-packages\sqlalchemy\pool\base.py", line 899, in __connect
    with util.safe_reraise():
         ~~~~~~~~~~~~~~~~~^^
  File "D:\BudgetTracker_Backend\.venv\Lib\site-packages\sqlalchemy\util\langhelpers.py", line 224, in __exit__
    raise exc_value.with_traceback(exc_tb)
  File "D:\BudgetTracker_Backend\.venv\Lib\site-packages\sqlalchemy\pool\base.py", line 895, in __connect
    self.dbapi_connection = connection = pool._invoke_creator(self)
                                         ~~~~~~~~~~~~~~~~~~~~^^^^^^
  File "D:\BudgetTracker_Backend\.venv\Lib\site-packages\sqlalchemy\engine\create.py", line 661, in connect
    return dialect.connect(*cargs, **cparams)
           ~~~~~~~~~~~~~~~^^^^^^^^^^^^^^^^^^^
  File "D:\BudgetTracker_Backend\.venv\Lib\site-packages\sqlalchemy\engine\default.py", line 629, in connect
    return self.loaded_dbapi.connect(*cargs, **cparams)  # type: ignore[no-any-return]  # NOQA: E501
           ~~~~~~~~~~~~~~~~~~~~~~~~~^^^^^^^^^^^^^^^^^^^
  File "D:\BudgetTracker_Backend\.venv\Lib\site-packages\psycopg2\__init__.py", line 135, in connect
    conn = _connect(dsn, connection_factory=connection_factory, **kwasync)
psycopg2.OperationalError: connection to server at "localhost" (::1), port 5432 failed: FATAL:  database "budgettracker" does not exist


The above exception was the direct cause of the following exception:

Traceback (most recent call last):
  File "D:\BudgetTracker_Backend\routes\auth_routes.py", line 133, in login
    user = User.query.filter_by(email=email).first()
  File "D:\BudgetTracker_Backend\.venv\Lib\site-packages\sqlalchemy\orm\query.py", line 2759, in first
    return self.limit(1)._iter().first()  # type: ignore
           ~~~~~~~~~~~~~~~~~~~^^
  File "D:\BudgetTracker_Backend\.venv\Lib\site-packages\sqlalchemy\orm\query.py", line 2857, in _iter
    result: Union[ScalarResult[_T], Result[_T]] = self.session.execute(
                                                  ~~~~~~~~~~~~~~~~~~~~^
        statement,
        ^^^^^^^^^^
        params,
        ^^^^^^^
        execution_options={"_sa_orm_load_options": self.load_options},
        ^^^^^^^^^^^^^^^^^^^^^^^^^^^^^^^^^^^^^^^^^^^^^^^^^^^^^^^^^^^^^^
    )
    ^
  File "D:\BudgetTracker_Backend\.venv\Lib\site-packages\sqlalchemy\orm\session.py", line 2365, in execute
    return self._execute_internal(
           ~~~~~~~~~~~~~~~~~~~~~~^
        statement,
        ^^^^^^^^^^
    ...<4 lines>...
        _add_event=_add_event,
        ^^^^^^^^^^^^^^^^^^^^^^
    )
    ^
  File "D:\BudgetTracker_Backend\.venv\Lib\site-packages\sqlalchemy\orm\session.py", line 2241, in _execute_internal
    conn = self._connection_for_bind(bind)
  File "D:\BudgetTracker_Backend\.venv\Lib\site-packages\sqlalchemy\orm\session.py", line 2110, in _connection_for_bind
    return trans._connection_for_bind(engine, execution_options)
           ~~~~~~~~~~~~~~~~~~~~~~~~~~^^^^^^^^^^^^^^^^^^^^^^^^^^^
  File "<string>", line 2, in _connection_for_bind
  File "D:\BudgetTracker_Backend\.venv\Lib\site-packages\sqlalchemy\orm\state_changes.py", line 137, in _go
    ret_value = fn(self, *arg, **kw)
  File "D:\BudgetTracker_Backend\.venv\Lib\site-packages\sqlalchemy\orm\session.py", line 1189, in _connection_for_bind
    conn = bind.connect()
  File "D:\BudgetTracker_Backend\.venv\Lib\site-packages\sqlalchemy\engine\base.py", line 3277, in connect
    return self._connection_cls(self)
           ~~~~~~~~~~~~~~~~~~~~^^^^^^
  File "D:\BudgetTracker_Backend\.venv\Lib\site-packages\sqlalchemy\engine\base.py", line 145, in __init__
    Connection._handle_dbapi_exception_noconnection(
    ~~~~~~~~~~~~~~~~~~~~~~~~~~~~~~~~~~~~~~~~~~~~~~~^
        err, dialect, engine
        ^^^^^^^^^^^^^^^^^^^^
    )
    ^
  File "D:\BudgetTracker_Backend\.venv\Lib\site-packages\sqlalchemy\engine\base.py", line 2440, in _handle_dbapi_exception_noconnection
    raise sqlalchemy_exception.with_traceback(exc_info[2]) from e
  File "D:\BudgetTracker_Backend\.venv\Lib\site-packages\sqlalchemy\engine\base.py", line 143, in __init__
    self._dbapi_connection = engine.raw_connection()
                             ~~~~~~~~~~~~~~~~~~~~~^^
  File "D:\BudgetTracker_Backend\.venv\Lib\site-packages\sqlalchemy\engine\base.py", line 3301, in raw_connection
    return self.pool.connect()
           ~~~~~~~~~~~~~~~~~^^
  File "D:\BudgetTracker_Backend\.venv\Lib\site-packages\sqlalchemy\pool\base.py", line 447, in connect
    return _ConnectionFairy._checkout(self)
           ~~~~~~~~~~~~~~~~~~~~~~~~~~^^^^^^
  File "D:\BudgetTracker_Backend\.venv\Lib\site-packages\sqlalchemy\pool\base.py", line 1264, in _checkout
    fairy = _ConnectionRecord.checkout(pool)
  File "D:\BudgetTracker_Backend\.venv\Lib\site-packages\sqlalchemy\pool\base.py", line 711, in checkout
    rec = pool._do_get()
  File "D:\BudgetTracker_Backend\.venv\Lib\site-packages\sqlalchemy\pool\impl.py", line 177, in _do_get
    with util.safe_reraise():
         ~~~~~~~~~~~~~~~~~^^
  File "D:\BudgetTracker_Backend\.venv\Lib\site-packages\sqlalchemy\util\langhelpers.py", line 224, in __exit__
    raise exc_value.with_traceback(exc_tb)
  File "D:\BudgetTracker_Backend\.venv\Lib\site-packages\sqlalchemy\pool\impl.py", line 175, in _do_get
    return self._create_connection()
           ~~~~~~~~~~~~~~~~~~~~~~~^^
  File "D:\BudgetTracker_Backend\.venv\Lib\site-packages\sqlalchemy\pool\base.py", line 388, in _create_connection
    return _ConnectionRecord(self)
  File "D:\BudgetTracker_Backend\.venv\Lib\site-packages\sqlalchemy\pool\base.py", line 673, in __init__
    self.__connect()
    ~~~~~~~~~~~~~~^^
  File "D:\BudgetTracker_Backend\.venv\Lib\site-packages\sqlalchemy\pool\base.py", line 899, in __connect
    with util.safe_reraise():
         ~~~~~~~~~~~~~~~~~^^
  File "D:\BudgetTracker_Backend\.venv\Lib\site-packages\sqlalchemy\util\langhelpers.py", line 224, in __exit__
    raise exc_value.with_traceback(exc_tb)
  File "D:\BudgetTracker_Backend\.venv\Lib\site-packages\sqlalchemy\pool\base.py", line 895, in __connect
    self.dbapi_connection = connection = pool._invoke_creator(self)
                                         ~~~~~~~~~~~~~~~~~~~~^^^^^^
  File "D:\BudgetTracker_Backend\.venv\Lib\site-packages\sqlalchemy\engine\create.py", line 661, in connect
    return dialect.connect(*cargs, **cparams)
           ~~~~~~~~~~~~~~~^^^^^^^^^^^^^^^^^^^
  File "D:\BudgetTracker_Backend\.venv\Lib\site-packages\sqlalchemy\engine\default.py", line 629, in connect
    return self.loaded_dbapi.connect(*cargs, **cparams)  # type: ignore[no-any-return]  # NOQA: E501
           ~~~~~~~~~~~~~~~~~~~~~~~~~^^^^^^^^^^^^^^^^^^^
  File "D:\BudgetTracker_Backend\.venv\Lib\site-packages\psycopg2\__init__.py", line 135, in connect
    conn = _connect(dsn, connection_factory=connection_factory, **kwasync)
sqlalchemy.exc.OperationalError: (psycopg2.OperationalError) connection to server at "localhost" (::1), port 5432 failed: FATAL:  database "budgettracker" does not exist

(Background on this error at: https://sqlalche.me/e/20/e3q8)
2025-09-19 17:36:54,358 [ERROR] app: ❌ Error in /auth/login: (psycopg2.OperationalError) connection to server at "localhost" (::1), port 5432 failed: FATAL:  database "budgettracker" does not exist

(Background on this error at: https://sqlalche.me/e/20/e3q8)
Traceback (most recent call last):
  File "D:\BudgetTracker_Backend\.venv\Lib\site-packages\sqlalchemy\engine\base.py", line 143, in __init__
    self._dbapi_connection = engine.raw_connection()
                             ~~~~~~~~~~~~~~~~~~~~~^^
  File "D:\BudgetTracker_Backend\.venv\Lib\site-packages\sqlalchemy\engine\base.py", line 3301, in raw_connection
    return self.pool.connect()
           ~~~~~~~~~~~~~~~~~^^
  File "D:\BudgetTracker_Backend\.venv\Lib\site-packages\sqlalchemy\pool\base.py", line 447, in connect
    return _ConnectionFairy._checkout(self)
           ~~~~~~~~~~~~~~~~~~~~~~~~~~^^^^^^
  File "D:\BudgetTracker_Backend\.venv\Lib\site-packages\sqlalchemy\pool\base.py", line 1264, in _checkout
    fairy = _ConnectionRecord.checkout(pool)
  File "D:\BudgetTracker_Backend\.venv\Lib\site-packages\sqlalchemy\pool\base.py", line 711, in checkout
    rec = pool._do_get()
  File "D:\BudgetTracker_Backend\.venv\Lib\site-packages\sqlalchemy\pool\impl.py", line 177, in _do_get
    with util.safe_reraise():
         ~~~~~~~~~~~~~~~~~^^
  File "D:\BudgetTracker_Backend\.venv\Lib\site-packages\sqlalchemy\util\langhelpers.py", line 224, in __exit__
    raise exc_value.with_traceback(exc_tb)
  File "D:\BudgetTracker_Backend\.venv\Lib\site-packages\sqlalchemy\pool\impl.py", line 175, in _do_get
    return self._create_connection()
           ~~~~~~~~~~~~~~~~~~~~~~~^^
  File "D:\BudgetTracker_Backend\.venv\Lib\site-packages\sqlalchemy\pool\base.py", line 388, in _create_connection
    return _ConnectionRecord(self)
  File "D:\BudgetTracker_Backend\.venv\Lib\site-packages\sqlalchemy\pool\base.py", line 673, in __init__
    self.__connect()
    ~~~~~~~~~~~~~~^^
  File "D:\BudgetTracker_Backend\.venv\Lib\site-packages\sqlalchemy\pool\base.py", line 899, in __connect
    with util.safe_reraise():
         ~~~~~~~~~~~~~~~~~^^
  File "D:\BudgetTracker_Backend\.venv\Lib\site-packages\sqlalchemy\util\langhelpers.py", line 224, in __exit__
    raise exc_value.with_traceback(exc_tb)
  File "D:\BudgetTracker_Backend\.venv\Lib\site-packages\sqlalchemy\pool\base.py", line 895, in __connect
    self.dbapi_connection = connection = pool._invoke_creator(self)
                                         ~~~~~~~~~~~~~~~~~~~~^^^^^^
  File "D:\BudgetTracker_Backend\.venv\Lib\site-packages\sqlalchemy\engine\create.py", line 661, in connect
    return dialect.connect(*cargs, **cparams)
           ~~~~~~~~~~~~~~~^^^^^^^^^^^^^^^^^^^
  File "D:\BudgetTracker_Backend\.venv\Lib\site-packages\sqlalchemy\engine\default.py", line 629, in connect
    return self.loaded_dbapi.connect(*cargs, **cparams)  # type: ignore[no-any-return]  # NOQA: E501
           ~~~~~~~~~~~~~~~~~~~~~~~~~^^^^^^^^^^^^^^^^^^^
  File "D:\BudgetTracker_Backend\.venv\Lib\site-packages\psycopg2\__init__.py", line 135, in connect
    conn = _connect(dsn, connection_factory=connection_factory, **kwasync)
psycopg2.OperationalError: connection to server at "localhost" (::1), port 5432 failed: FATAL:  database "budgettracker" does not exist


The above exception was the direct cause of the following exception:

Traceback (most recent call last):
  File "D:\BudgetTracker_Backend\routes\auth_routes.py", line 133, in login
    user = User.query.filter_by(email=email).first()
  File "D:\BudgetTracker_Backend\.venv\Lib\site-packages\sqlalchemy\orm\query.py", line 2759, in first
    return self.limit(1)._iter().first()  # type: ignore
           ~~~~~~~~~~~~~~~~~~~^^
  File "D:\BudgetTracker_Backend\.venv\Lib\site-packages\sqlalchemy\orm\query.py", line 2857, in _iter
    result: Union[ScalarResult[_T], Result[_T]] = self.session.execute(
                                                  ~~~~~~~~~~~~~~~~~~~~^
        statement,
        ^^^^^^^^^^
        params,
        ^^^^^^^
        execution_options={"_sa_orm_load_options": self.load_options},
        ^^^^^^^^^^^^^^^^^^^^^^^^^^^^^^^^^^^^^^^^^^^^^^^^^^^^^^^^^^^^^^
    )
    ^
  File "D:\BudgetTracker_Backend\.venv\Lib\site-packages\sqlalchemy\orm\session.py", line 2365, in execute
    return self._execute_internal(
           ~~~~~~~~~~~~~~~~~~~~~~^
        statement,
        ^^^^^^^^^^
    ...<4 lines>...
        _add_event=_add_event,
        ^^^^^^^^^^^^^^^^^^^^^^
    )
    ^
  File "D:\BudgetTracker_Backend\.venv\Lib\site-packages\sqlalchemy\orm\session.py", line 2241, in _execute_internal
    conn = self._connection_for_bind(bind)
  File "D:\BudgetTracker_Backend\.venv\Lib\site-packages\sqlalchemy\orm\session.py", line 2110, in _connection_for_bind
    return trans._connection_for_bind(engine, execution_options)
           ~~~~~~~~~~~~~~~~~~~~~~~~~~^^^^^^^^^^^^^^^^^^^^^^^^^^^
  File "<string>", line 2, in _connection_for_bind
  File "D:\BudgetTracker_Backend\.venv\Lib\site-packages\sqlalchemy\orm\state_changes.py", line 137, in _go
    ret_value = fn(self, *arg, **kw)
  File "D:\BudgetTracker_Backend\.venv\Lib\site-packages\sqlalchemy\orm\session.py", line 1189, in _connection_for_bind
    conn = bind.connect()
  File "D:\BudgetTracker_Backend\.venv\Lib\site-packages\sqlalchemy\engine\base.py", line 3277, in connect
    return self._connection_cls(self)
           ~~~~~~~~~~~~~~~~~~~~^^^^^^
  File "D:\BudgetTracker_Backend\.venv\Lib\site-packages\sqlalchemy\engine\base.py", line 145, in __init__
    Connection._handle_dbapi_exception_noconnection(
    ~~~~~~~~~~~~~~~~~~~~~~~~~~~~~~~~~~~~~~~~~~~~~~~^
        err, dialect, engine
        ^^^^^^^^^^^^^^^^^^^^
    )
    ^
  File "D:\BudgetTracker_Backend\.venv\Lib\site-packages\sqlalchemy\engine\base.py", line 2440, in _handle_dbapi_exception_noconnection
    raise sqlalchemy_exception.with_traceback(exc_info[2]) from e
  File "D:\BudgetTracker_Backend\.venv\Lib\site-packages\sqlalchemy\engine\base.py", line 143, in __init__
    self._dbapi_connection = engine.raw_connection()
                             ~~~~~~~~~~~~~~~~~~~~~^^
  File "D:\BudgetTracker_Backend\.venv\Lib\site-packages\sqlalchemy\engine\base.py", line 3301, in raw_connection
    return self.pool.connect()
           ~~~~~~~~~~~~~~~~~^^
  File "D:\BudgetTracker_Backend\.venv\Lib\site-packages\sqlalchemy\pool\base.py", line 447, in connect
    return _ConnectionFairy._checkout(self)
           ~~~~~~~~~~~~~~~~~~~~~~~~~~^^^^^^
  File "D:\BudgetTracker_Backend\.venv\Lib\site-packages\sqlalchemy\pool\base.py", line 1264, in _checkout
    fairy = _ConnectionRecord.checkout(pool)
  File "D:\BudgetTracker_Backend\.venv\Lib\site-packages\sqlalchemy\pool\base.py", line 711, in checkout
    rec = pool._do_get()
  File "D:\BudgetTracker_Backend\.venv\Lib\site-packages\sqlalchemy\pool\impl.py", line 177, in _do_get
    with util.safe_reraise():
         ~~~~~~~~~~~~~~~~~^^
  File "D:\BudgetTracker_Backend\.venv\Lib\site-packages\sqlalchemy\util\langhelpers.py", line 224, in __exit__
    raise exc_value.with_traceback(exc_tb)
  File "D:\BudgetTracker_Backend\.venv\Lib\site-packages\sqlalchemy\pool\impl.py", line 175, in _do_get
    return self._create_connection()
           ~~~~~~~~~~~~~~~~~~~~~~~^^
  File "D:\BudgetTracker_Backend\.venv\Lib\site-packages\sqlalchemy\pool\base.py", line 388, in _create_connection
    return _ConnectionRecord(self)
  File "D:\BudgetTracker_Backend\.venv\Lib\site-packages\sqlalchemy\pool\base.py", line 673, in __init__
    self.__connect()
    ~~~~~~~~~~~~~~^^
  File "D:\BudgetTracker_Backend\.venv\Lib\site-packages\sqlalchemy\pool\base.py", line 899, in __connect
    with util.safe_reraise():
         ~~~~~~~~~~~~~~~~~^^
  File "D:\BudgetTracker_Backend\.venv\Lib\site-packages\sqlalchemy\util\langhelpers.py", line 224, in __exit__
    raise exc_value.with_traceback(exc_tb)
  File "D:\BudgetTracker_Backend\.venv\Lib\site-packages\sqlalchemy\pool\base.py", line 895, in __connect
    self.dbapi_connection = connection = pool._invoke_creator(self)
                                         ~~~~~~~~~~~~~~~~~~~~^^^^^^
  File "D:\BudgetTracker_Backend\.venv\Lib\site-packages\sqlalchemy\engine\create.py", line 661, in connect
    return dialect.connect(*cargs, **cparams)
           ~~~~~~~~~~~~~~~^^^^^^^^^^^^^^^^^^^
  File "D:\BudgetTracker_Backend\.venv\Lib\site-packages\sqlalchemy\engine\default.py", line 629, in connect
    return self.loaded_dbapi.connect(*cargs, **cparams)  # type: ignore[no-any-return]  # NOQA: E501
           ~~~~~~~~~~~~~~~~~~~~~~~~~^^^^^^^^^^^^^^^^^^^
  File "D:\BudgetTracker_Backend\.venv\Lib\site-packages\psycopg2\__init__.py", line 135, in connect
    conn = _connect(dsn, connection_factory=connection_factory, **kwasync)
sqlalchemy.exc.OperationalError: (psycopg2.OperationalError) connection to server at "localhost" (::1), port 5432 failed: FATAL:  database "budgettracker" does not exist

(Background on this error at: https://sqlalche.me/e/20/e3q8)
2025-09-19 18:33:18,759 [ERROR] app: ❌ Error in /auth/login: (psycopg2.OperationalError) connection to server at "localhost" (::1), port 5432 failed: FATAL:  database "budgettracker" does not exist

(Background on this error at: https://sqlalche.me/e/20/e3q8)
Traceback (most recent call last):
  File "D:\BudgetTracker_Backend\.venv\Lib\site-packages\sqlalchemy\engine\base.py", line 143, in __init__
    self._dbapi_connection = engine.raw_connection()
                             ~~~~~~~~~~~~~~~~~~~~~^^
  File "D:\BudgetTracker_Backend\.venv\Lib\site-packages\sqlalchemy\engine\base.py", line 3301, in raw_connection
    return self.pool.connect()
           ~~~~~~~~~~~~~~~~~^^
  File "D:\BudgetTracker_Backend\.venv\Lib\site-packages\sqlalchemy\pool\base.py", line 447, in connect
    return _ConnectionFairy._checkout(self)
           ~~~~~~~~~~~~~~~~~~~~~~~~~~^^^^^^
  File "D:\BudgetTracker_Backend\.venv\Lib\site-packages\sqlalchemy\pool\base.py", line 1264, in _checkout
    fairy = _ConnectionRecord.checkout(pool)
  File "D:\BudgetTracker_Backend\.venv\Lib\site-packages\sqlalchemy\pool\base.py", line 711, in checkout
    rec = pool._do_get()
  File "D:\BudgetTracker_Backend\.venv\Lib\site-packages\sqlalchemy\pool\impl.py", line 177, in _do_get
    with util.safe_reraise():
         ~~~~~~~~~~~~~~~~~^^
  File "D:\BudgetTracker_Backend\.venv\Lib\site-packages\sqlalchemy\util\langhelpers.py", line 224, in __exit__
    raise exc_value.with_traceback(exc_tb)
  File "D:\BudgetTracker_Backend\.venv\Lib\site-packages\sqlalchemy\pool\impl.py", line 175, in _do_get
    return self._create_connection()
           ~~~~~~~~~~~~~~~~~~~~~~~^^
  File "D:\BudgetTracker_Backend\.venv\Lib\site-packages\sqlalchemy\pool\base.py", line 388, in _create_connection
    return _ConnectionRecord(self)
  File "D:\BudgetTracker_Backend\.venv\Lib\site-packages\sqlalchemy\pool\base.py", line 673, in __init__
    self.__connect()
    ~~~~~~~~~~~~~~^^
  File "D:\BudgetTracker_Backend\.venv\Lib\site-packages\sqlalchemy\pool\base.py", line 899, in __connect
    with util.safe_reraise():
         ~~~~~~~~~~~~~~~~~^^
  File "D:\BudgetTracker_Backend\.venv\Lib\site-packages\sqlalchemy\util\langhelpers.py", line 224, in __exit__
    raise exc_value.with_traceback(exc_tb)
  File "D:\BudgetTracker_Backend\.venv\Lib\site-packages\sqlalchemy\pool\base.py", line 895, in __connect
    self.dbapi_connection = connection = pool._invoke_creator(self)
                                         ~~~~~~~~~~~~~~~~~~~~^^^^^^
  File "D:\BudgetTracker_Backend\.venv\Lib\site-packages\sqlalchemy\engine\create.py", line 661, in connect
    return dialect.connect(*cargs, **cparams)
           ~~~~~~~~~~~~~~~^^^^^^^^^^^^^^^^^^^
  File "D:\BudgetTracker_Backend\.venv\Lib\site-packages\sqlalchemy\engine\default.py", line 629, in connect
    return self.loaded_dbapi.connect(*cargs, **cparams)  # type: ignore[no-any-return]  # NOQA: E501
           ~~~~~~~~~~~~~~~~~~~~~~~~~^^^^^^^^^^^^^^^^^^^
  File "D:\BudgetTracker_Backend\.venv\Lib\site-packages\psycopg2\__init__.py", line 135, in connect
    conn = _connect(dsn, connection_factory=connection_factory, **kwasync)
psycopg2.OperationalError: connection to server at "localhost" (::1), port 5432 failed: FATAL:  database "budgettracker" does not exist


The above exception was the direct cause of the following exception:

Traceback (most recent call last):
  File "D:\BudgetTracker_Backend\routes\auth_routes.py", line 133, in login
    user = User.query.filter_by(email=email).first()
  File "D:\BudgetTracker_Backend\.venv\Lib\site-packages\sqlalchemy\orm\query.py", line 2759, in first
    return self.limit(1)._iter().first()  # type: ignore
           ~~~~~~~~~~~~~~~~~~~^^
  File "D:\BudgetTracker_Backend\.venv\Lib\site-packages\sqlalchemy\orm\query.py", line 2857, in _iter
    result: Union[ScalarResult[_T], Result[_T]] = self.session.execute(
                                                  ~~~~~~~~~~~~~~~~~~~~^
        statement,
        ^^^^^^^^^^
        params,
        ^^^^^^^
        execution_options={"_sa_orm_load_options": self.load_options},
        ^^^^^^^^^^^^^^^^^^^^^^^^^^^^^^^^^^^^^^^^^^^^^^^^^^^^^^^^^^^^^^
    )
    ^
  File "D:\BudgetTracker_Backend\.venv\Lib\site-packages\sqlalchemy\orm\session.py", line 2365, in execute
    return self._execute_internal(
           ~~~~~~~~~~~~~~~~~~~~~~^
        statement,
        ^^^^^^^^^^
    ...<4 lines>...
        _add_event=_add_event,
        ^^^^^^^^^^^^^^^^^^^^^^
    )
    ^
  File "D:\BudgetTracker_Backend\.venv\Lib\site-packages\sqlalchemy\orm\session.py", line 2241, in _execute_internal
    conn = self._connection_for_bind(bind)
  File "D:\BudgetTracker_Backend\.venv\Lib\site-packages\sqlalchemy\orm\session.py", line 2110, in _connection_for_bind
    return trans._connection_for_bind(engine, execution_options)
           ~~~~~~~~~~~~~~~~~~~~~~~~~~^^^^^^^^^^^^^^^^^^^^^^^^^^^
  File "<string>", line 2, in _connection_for_bind
  File "D:\BudgetTracker_Backend\.venv\Lib\site-packages\sqlalchemy\orm\state_changes.py", line 137, in _go
    ret_value = fn(self, *arg, **kw)
  File "D:\BudgetTracker_Backend\.venv\Lib\site-packages\sqlalchemy\orm\session.py", line 1189, in _connection_for_bind
    conn = bind.connect()
  File "D:\BudgetTracker_Backend\.venv\Lib\site-packages\sqlalchemy\engine\base.py", line 3277, in connect
    return self._connection_cls(self)
           ~~~~~~~~~~~~~~~~~~~~^^^^^^
  File "D:\BudgetTracker_Backend\.venv\Lib\site-packages\sqlalchemy\engine\base.py", line 145, in __init__
    Connection._handle_dbapi_exception_noconnection(
    ~~~~~~~~~~~~~~~~~~~~~~~~~~~~~~~~~~~~~~~~~~~~~~~^
        err, dialect, engine
        ^^^^^^^^^^^^^^^^^^^^
    )
    ^
  File "D:\BudgetTracker_Backend\.venv\Lib\site-packages\sqlalchemy\engine\base.py", line 2440, in _handle_dbapi_exception_noconnection
    raise sqlalchemy_exception.with_traceback(exc_info[2]) from e
  File "D:\BudgetTracker_Backend\.venv\Lib\site-packages\sqlalchemy\engine\base.py", line 143, in __init__
    self._dbapi_connection = engine.raw_connection()
                             ~~~~~~~~~~~~~~~~~~~~~^^
  File "D:\BudgetTracker_Backend\.venv\Lib\site-packages\sqlalchemy\engine\base.py", line 3301, in raw_connection
    return self.pool.connect()
           ~~~~~~~~~~~~~~~~~^^
  File "D:\BudgetTracker_Backend\.venv\Lib\site-packages\sqlalchemy\pool\base.py", line 447, in connect
    return _ConnectionFairy._checkout(self)
           ~~~~~~~~~~~~~~~~~~~~~~~~~~^^^^^^
  File "D:\BudgetTracker_Backend\.venv\Lib\site-packages\sqlalchemy\pool\base.py", line 1264, in _checkout
    fairy = _ConnectionRecord.checkout(pool)
  File "D:\BudgetTracker_Backend\.venv\Lib\site-packages\sqlalchemy\pool\base.py", line 711, in checkout
    rec = pool._do_get()
  File "D:\BudgetTracker_Backend\.venv\Lib\site-packages\sqlalchemy\pool\impl.py", line 177, in _do_get
    with util.safe_reraise():
         ~~~~~~~~~~~~~~~~~^^
  File "D:\BudgetTracker_Backend\.venv\Lib\site-packages\sqlalchemy\util\langhelpers.py", line 224, in __exit__
    raise exc_value.with_traceback(exc_tb)
  File "D:\BudgetTracker_Backend\.venv\Lib\site-packages\sqlalchemy\pool\impl.py", line 175, in _do_get
    return self._create_connection()
           ~~~~~~~~~~~~~~~~~~~~~~~^^
  File "D:\BudgetTracker_Backend\.venv\Lib\site-packages\sqlalchemy\pool\base.py", line 388, in _create_connection
    return _ConnectionRecord(self)
  File "D:\BudgetTracker_Backend\.venv\Lib\site-packages\sqlalchemy\pool\base.py", line 673, in __init__
    self.__connect()
    ~~~~~~~~~~~~~~^^
  File "D:\BudgetTracker_Backend\.venv\Lib\site-packages\sqlalchemy\pool\base.py", line 899, in __connect
    with util.safe_reraise():
         ~~~~~~~~~~~~~~~~~^^
  File "D:\BudgetTracker_Backend\.venv\Lib\site-packages\sqlalchemy\util\langhelpers.py", line 224, in __exit__
    raise exc_value.with_traceback(exc_tb)
  File "D:\BudgetTracker_Backend\.venv\Lib\site-packages\sqlalchemy\pool\base.py", line 895, in __connect
    self.dbapi_connection = connection = pool._invoke_creator(self)
                                         ~~~~~~~~~~~~~~~~~~~~^^^^^^
  File "D:\BudgetTracker_Backend\.venv\Lib\site-packages\sqlalchemy\engine\create.py", line 661, in connect
    return dialect.connect(*cargs, **cparams)
           ~~~~~~~~~~~~~~~^^^^^^^^^^^^^^^^^^^
  File "D:\BudgetTracker_Backend\.venv\Lib\site-packages\sqlalchemy\engine\default.py", line 629, in connect
    return self.loaded_dbapi.connect(*cargs, **cparams)  # type: ignore[no-any-return]  # NOQA: E501
           ~~~~~~~~~~~~~~~~~~~~~~~~~^^^^^^^^^^^^^^^^^^^
  File "D:\BudgetTracker_Backend\.venv\Lib\site-packages\psycopg2\__init__.py", line 135, in connect
    conn = _connect(dsn, connection_factory=connection_factory, **kwasync)
sqlalchemy.exc.OperationalError: (psycopg2.OperationalError) connection to server at "localhost" (::1), port 5432 failed: FATAL:  database "budgettracker" does not exist

(Background on this error at: https://sqlalche.me/e/20/e3q8)
2025-09-19 18:33:19,468 [ERROR] app: ❌ Error in /auth/login: (psycopg2.OperationalError) connection to server at "localhost" (::1), port 5432 failed: FATAL:  database "budgettracker" does not exist

(Background on this error at: https://sqlalche.me/e/20/e3q8)
Traceback (most recent call last):
  File "D:\BudgetTracker_Backend\.venv\Lib\site-packages\sqlalchemy\engine\base.py", line 143, in __init__
    self._dbapi_connection = engine.raw_connection()
                             ~~~~~~~~~~~~~~~~~~~~~^^
  File "D:\BudgetTracker_Backend\.venv\Lib\site-packages\sqlalchemy\engine\base.py", line 3301, in raw_connection
    return self.pool.connect()
           ~~~~~~~~~~~~~~~~~^^
  File "D:\BudgetTracker_Backend\.venv\Lib\site-packages\sqlalchemy\pool\base.py", line 447, in connect
    return _ConnectionFairy._checkout(self)
           ~~~~~~~~~~~~~~~~~~~~~~~~~~^^^^^^
  File "D:\BudgetTracker_Backend\.venv\Lib\site-packages\sqlalchemy\pool\base.py", line 1264, in _checkout
    fairy = _ConnectionRecord.checkout(pool)
  File "D:\BudgetTracker_Backend\.venv\Lib\site-packages\sqlalchemy\pool\base.py", line 711, in checkout
    rec = pool._do_get()
  File "D:\BudgetTracker_Backend\.venv\Lib\site-packages\sqlalchemy\pool\impl.py", line 177, in _do_get
    with util.safe_reraise():
         ~~~~~~~~~~~~~~~~~^^
  File "D:\BudgetTracker_Backend\.venv\Lib\site-packages\sqlalchemy\util\langhelpers.py", line 224, in __exit__
    raise exc_value.with_traceback(exc_tb)
  File "D:\BudgetTracker_Backend\.venv\Lib\site-packages\sqlalchemy\pool\impl.py", line 175, in _do_get
    return self._create_connection()
           ~~~~~~~~~~~~~~~~~~~~~~~^^
  File "D:\BudgetTracker_Backend\.venv\Lib\site-packages\sqlalchemy\pool\base.py", line 388, in _create_connection
    return _ConnectionRecord(self)
  File "D:\BudgetTracker_Backend\.venv\Lib\site-packages\sqlalchemy\pool\base.py", line 673, in __init__
    self.__connect()
    ~~~~~~~~~~~~~~^^
  File "D:\BudgetTracker_Backend\.venv\Lib\site-packages\sqlalchemy\pool\base.py", line 899, in __connect
    with util.safe_reraise():
         ~~~~~~~~~~~~~~~~~^^
  File "D:\BudgetTracker_Backend\.venv\Lib\site-packages\sqlalchemy\util\langhelpers.py", line 224, in __exit__
    raise exc_value.with_traceback(exc_tb)
  File "D:\BudgetTracker_Backend\.venv\Lib\site-packages\sqlalchemy\pool\base.py", line 895, in __connect
    self.dbapi_connection = connection = pool._invoke_creator(self)
                                         ~~~~~~~~~~~~~~~~~~~~^^^^^^
  File "D:\BudgetTracker_Backend\.venv\Lib\site-packages\sqlalchemy\engine\create.py", line 661, in connect
    return dialect.connect(*cargs, **cparams)
           ~~~~~~~~~~~~~~~^^^^^^^^^^^^^^^^^^^
  File "D:\BudgetTracker_Backend\.venv\Lib\site-packages\sqlalchemy\engine\default.py", line 629, in connect
    return self.loaded_dbapi.connect(*cargs, **cparams)  # type: ignore[no-any-return]  # NOQA: E501
           ~~~~~~~~~~~~~~~~~~~~~~~~~^^^^^^^^^^^^^^^^^^^
  File "D:\BudgetTracker_Backend\.venv\Lib\site-packages\psycopg2\__init__.py", line 135, in connect
    conn = _connect(dsn, connection_factory=connection_factory, **kwasync)
psycopg2.OperationalError: connection to server at "localhost" (::1), port 5432 failed: FATAL:  database "budgettracker" does not exist


The above exception was the direct cause of the following exception:

Traceback (most recent call last):
  File "D:\BudgetTracker_Backend\routes\auth_routes.py", line 133, in login
    user = User.query.filter_by(email=email).first()
  File "D:\BudgetTracker_Backend\.venv\Lib\site-packages\sqlalchemy\orm\query.py", line 2759, in first
    return self.limit(1)._iter().first()  # type: ignore
           ~~~~~~~~~~~~~~~~~~~^^
  File "D:\BudgetTracker_Backend\.venv\Lib\site-packages\sqlalchemy\orm\query.py", line 2857, in _iter
    result: Union[ScalarResult[_T], Result[_T]] = self.session.execute(
                                                  ~~~~~~~~~~~~~~~~~~~~^
        statement,
        ^^^^^^^^^^
        params,
        ^^^^^^^
        execution_options={"_sa_orm_load_options": self.load_options},
        ^^^^^^^^^^^^^^^^^^^^^^^^^^^^^^^^^^^^^^^^^^^^^^^^^^^^^^^^^^^^^^
    )
    ^
  File "D:\BudgetTracker_Backend\.venv\Lib\site-packages\sqlalchemy\orm\session.py", line 2365, in execute
    return self._execute_internal(
           ~~~~~~~~~~~~~~~~~~~~~~^
        statement,
        ^^^^^^^^^^
    ...<4 lines>...
        _add_event=_add_event,
        ^^^^^^^^^^^^^^^^^^^^^^
    )
    ^
  File "D:\BudgetTracker_Backend\.venv\Lib\site-packages\sqlalchemy\orm\session.py", line 2241, in _execute_internal
    conn = self._connection_for_bind(bind)
  File "D:\BudgetTracker_Backend\.venv\Lib\site-packages\sqlalchemy\orm\session.py", line 2110, in _connection_for_bind
    return trans._connection_for_bind(engine, execution_options)
           ~~~~~~~~~~~~~~~~~~~~~~~~~~^^^^^^^^^^^^^^^^^^^^^^^^^^^
  File "<string>", line 2, in _connection_for_bind
  File "D:\BudgetTracker_Backend\.venv\Lib\site-packages\sqlalchemy\orm\state_changes.py", line 137, in _go
    ret_value = fn(self, *arg, **kw)
  File "D:\BudgetTracker_Backend\.venv\Lib\site-packages\sqlalchemy\orm\session.py", line 1189, in _connection_for_bind
    conn = bind.connect()
  File "D:\BudgetTracker_Backend\.venv\Lib\site-packages\sqlalchemy\engine\base.py", line 3277, in connect
    return self._connection_cls(self)
           ~~~~~~~~~~~~~~~~~~~~^^^^^^
  File "D:\BudgetTracker_Backend\.venv\Lib\site-packages\sqlalchemy\engine\base.py", line 145, in __init__
    Connection._handle_dbapi_exception_noconnection(
    ~~~~~~~~~~~~~~~~~~~~~~~~~~~~~~~~~~~~~~~~~~~~~~~^
        err, dialect, engine
        ^^^^^^^^^^^^^^^^^^^^
    )
    ^
  File "D:\BudgetTracker_Backend\.venv\Lib\site-packages\sqlalchemy\engine\base.py", line 2440, in _handle_dbapi_exception_noconnection
    raise sqlalchemy_exception.with_traceback(exc_info[2]) from e
  File "D:\BudgetTracker_Backend\.venv\Lib\site-packages\sqlalchemy\engine\base.py", line 143, in __init__
    self._dbapi_connection = engine.raw_connection()
                             ~~~~~~~~~~~~~~~~~~~~~^^
  File "D:\BudgetTracker_Backend\.venv\Lib\site-packages\sqlalchemy\engine\base.py", line 3301, in raw_connection
    return self.pool.connect()
           ~~~~~~~~~~~~~~~~~^^
  File "D:\BudgetTracker_Backend\.venv\Lib\site-packages\sqlalchemy\pool\base.py", line 447, in connect
    return _ConnectionFairy._checkout(self)
           ~~~~~~~~~~~~~~~~~~~~~~~~~~^^^^^^
  File "D:\BudgetTracker_Backend\.venv\Lib\site-packages\sqlalchemy\pool\base.py", line 1264, in _checkout
    fairy = _ConnectionRecord.checkout(pool)
  File "D:\BudgetTracker_Backend\.venv\Lib\site-packages\sqlalchemy\pool\base.py", line 711, in checkout
    rec = pool._do_get()
  File "D:\BudgetTracker_Backend\.venv\Lib\site-packages\sqlalchemy\pool\impl.py", line 177, in _do_get
    with util.safe_reraise():
         ~~~~~~~~~~~~~~~~~^^
  File "D:\BudgetTracker_Backend\.venv\Lib\site-packages\sqlalchemy\util\langhelpers.py", line 224, in __exit__
    raise exc_value.with_traceback(exc_tb)
  File "D:\BudgetTracker_Backend\.venv\Lib\site-packages\sqlalchemy\pool\impl.py", line 175, in _do_get
    return self._create_connection()
           ~~~~~~~~~~~~~~~~~~~~~~~^^
  File "D:\BudgetTracker_Backend\.venv\Lib\site-packages\sqlalchemy\pool\base.py", line 388, in _create_connection
    return _ConnectionRecord(self)
  File "D:\BudgetTracker_Backend\.venv\Lib\site-packages\sqlalchemy\pool\base.py", line 673, in __init__
    self.__connect()
    ~~~~~~~~~~~~~~^^
  File "D:\BudgetTracker_Backend\.venv\Lib\site-packages\sqlalchemy\pool\base.py", line 899, in __connect
    with util.safe_reraise():
         ~~~~~~~~~~~~~~~~~^^
  File "D:\BudgetTracker_Backend\.venv\Lib\site-packages\sqlalchemy\util\langhelpers.py", line 224, in __exit__
    raise exc_value.with_traceback(exc_tb)
  File "D:\BudgetTracker_Backend\.venv\Lib\site-packages\sqlalchemy\pool\base.py", line 895, in __connect
    self.dbapi_connection = connection = pool._invoke_creator(self)
                                         ~~~~~~~~~~~~~~~~~~~~^^^^^^
  File "D:\BudgetTracker_Backend\.venv\Lib\site-packages\sqlalchemy\engine\create.py", line 661, in connect
    return dialect.connect(*cargs, **cparams)
           ~~~~~~~~~~~~~~~^^^^^^^^^^^^^^^^^^^
  File "D:\BudgetTracker_Backend\.venv\Lib\site-packages\sqlalchemy\engine\default.py", line 629, in connect
    return self.loaded_dbapi.connect(*cargs, **cparams)  # type: ignore[no-any-return]  # NOQA: E501
           ~~~~~~~~~~~~~~~~~~~~~~~~~^^^^^^^^^^^^^^^^^^^
  File "D:\BudgetTracker_Backend\.venv\Lib\site-packages\psycopg2\__init__.py", line 135, in connect
    conn = _connect(dsn, connection_factory=connection_factory, **kwasync)
sqlalchemy.exc.OperationalError: (psycopg2.OperationalError) connection to server at "localhost" (::1), port 5432 failed: FATAL:  database "budgettracker" does not exist

(Background on this error at: https://sqlalche.me/e/20/e3q8)
2025-09-19 18:33:19,806 [ERROR] app: ❌ Error in /auth/login: (psycopg2.OperationalError) connection to server at "localhost" (::1), port 5432 failed: FATAL:  database "budgettracker" does not exist

(Background on this error at: https://sqlalche.me/e/20/e3q8)
Traceback (most recent call last):
  File "D:\BudgetTracker_Backend\.venv\Lib\site-packages\sqlalchemy\engine\base.py", line 143, in __init__
    self._dbapi_connection = engine.raw_connection()
                             ~~~~~~~~~~~~~~~~~~~~~^^
  File "D:\BudgetTracker_Backend\.venv\Lib\site-packages\sqlalchemy\engine\base.py", line 3301, in raw_connection
    return self.pool.connect()
           ~~~~~~~~~~~~~~~~~^^
  File "D:\BudgetTracker_Backend\.venv\Lib\site-packages\sqlalchemy\pool\base.py", line 447, in connect
    return _ConnectionFairy._checkout(self)
           ~~~~~~~~~~~~~~~~~~~~~~~~~~^^^^^^
  File "D:\BudgetTracker_Backend\.venv\Lib\site-packages\sqlalchemy\pool\base.py", line 1264, in _checkout
    fairy = _ConnectionRecord.checkout(pool)
  File "D:\BudgetTracker_Backend\.venv\Lib\site-packages\sqlalchemy\pool\base.py", line 711, in checkout
    rec = pool._do_get()
  File "D:\BudgetTracker_Backend\.venv\Lib\site-packages\sqlalchemy\pool\impl.py", line 177, in _do_get
    with util.safe_reraise():
         ~~~~~~~~~~~~~~~~~^^
  File "D:\BudgetTracker_Backend\.venv\Lib\site-packages\sqlalchemy\util\langhelpers.py", line 224, in __exit__
    raise exc_value.with_traceback(exc_tb)
  File "D:\BudgetTracker_Backend\.venv\Lib\site-packages\sqlalchemy\pool\impl.py", line 175, in _do_get
    return self._create_connection()
           ~~~~~~~~~~~~~~~~~~~~~~~^^
  File "D:\BudgetTracker_Backend\.venv\Lib\site-packages\sqlalchemy\pool\base.py", line 388, in _create_connection
    return _ConnectionRecord(self)
  File "D:\BudgetTracker_Backend\.venv\Lib\site-packages\sqlalchemy\pool\base.py", line 673, in __init__
    self.__connect()
    ~~~~~~~~~~~~~~^^
  File "D:\BudgetTracker_Backend\.venv\Lib\site-packages\sqlalchemy\pool\base.py", line 899, in __connect
    with util.safe_reraise():
         ~~~~~~~~~~~~~~~~~^^
  File "D:\BudgetTracker_Backend\.venv\Lib\site-packages\sqlalchemy\util\langhelpers.py", line 224, in __exit__
    raise exc_value.with_traceback(exc_tb)
  File "D:\BudgetTracker_Backend\.venv\Lib\site-packages\sqlalchemy\pool\base.py", line 895, in __connect
    self.dbapi_connection = connection = pool._invoke_creator(self)
                                         ~~~~~~~~~~~~~~~~~~~~^^^^^^
  File "D:\BudgetTracker_Backend\.venv\Lib\site-packages\sqlalchemy\engine\create.py", line 661, in connect
    return dialect.connect(*cargs, **cparams)
           ~~~~~~~~~~~~~~~^^^^^^^^^^^^^^^^^^^
  File "D:\BudgetTracker_Backend\.venv\Lib\site-packages\sqlalchemy\engine\default.py", line 629, in connect
    return self.loaded_dbapi.connect(*cargs, **cparams)  # type: ignore[no-any-return]  # NOQA: E501
           ~~~~~~~~~~~~~~~~~~~~~~~~~^^^^^^^^^^^^^^^^^^^
  File "D:\BudgetTracker_Backend\.venv\Lib\site-packages\psycopg2\__init__.py", line 135, in connect
    conn = _connect(dsn, connection_factory=connection_factory, **kwasync)
psycopg2.OperationalError: connection to server at "localhost" (::1), port 5432 failed: FATAL:  database "budgettracker" does not exist


The above exception was the direct cause of the following exception:

Traceback (most recent call last):
  File "D:\BudgetTracker_Backend\routes\auth_routes.py", line 133, in login
    user = User.query.filter_by(email=email).first()
  File "D:\BudgetTracker_Backend\.venv\Lib\site-packages\sqlalchemy\orm\query.py", line 2759, in first
    return self.limit(1)._iter().first()  # type: ignore
           ~~~~~~~~~~~~~~~~~~~^^
  File "D:\BudgetTracker_Backend\.venv\Lib\site-packages\sqlalchemy\orm\query.py", line 2857, in _iter
    result: Union[ScalarResult[_T], Result[_T]] = self.session.execute(
                                                  ~~~~~~~~~~~~~~~~~~~~^
        statement,
        ^^^^^^^^^^
        params,
        ^^^^^^^
        execution_options={"_sa_orm_load_options": self.load_options},
        ^^^^^^^^^^^^^^^^^^^^^^^^^^^^^^^^^^^^^^^^^^^^^^^^^^^^^^^^^^^^^^
    )
    ^
  File "D:\BudgetTracker_Backend\.venv\Lib\site-packages\sqlalchemy\orm\session.py", line 2365, in execute
    return self._execute_internal(
           ~~~~~~~~~~~~~~~~~~~~~~^
        statement,
        ^^^^^^^^^^
    ...<4 lines>...
        _add_event=_add_event,
        ^^^^^^^^^^^^^^^^^^^^^^
    )
    ^
  File "D:\BudgetTracker_Backend\.venv\Lib\site-packages\sqlalchemy\orm\session.py", line 2241, in _execute_internal
    conn = self._connection_for_bind(bind)
  File "D:\BudgetTracker_Backend\.venv\Lib\site-packages\sqlalchemy\orm\session.py", line 2110, in _connection_for_bind
    return trans._connection_for_bind(engine, execution_options)
           ~~~~~~~~~~~~~~~~~~~~~~~~~~^^^^^^^^^^^^^^^^^^^^^^^^^^^
  File "<string>", line 2, in _connection_for_bind
  File "D:\BudgetTracker_Backend\.venv\Lib\site-packages\sqlalchemy\orm\state_changes.py", line 137, in _go
    ret_value = fn(self, *arg, **kw)
  File "D:\BudgetTracker_Backend\.venv\Lib\site-packages\sqlalchemy\orm\session.py", line 1189, in _connection_for_bind
    conn = bind.connect()
  File "D:\BudgetTracker_Backend\.venv\Lib\site-packages\sqlalchemy\engine\base.py", line 3277, in connect
    return self._connection_cls(self)
           ~~~~~~~~~~~~~~~~~~~~^^^^^^
  File "D:\BudgetTracker_Backend\.venv\Lib\site-packages\sqlalchemy\engine\base.py", line 145, in __init__
    Connection._handle_dbapi_exception_noconnection(
    ~~~~~~~~~~~~~~~~~~~~~~~~~~~~~~~~~~~~~~~~~~~~~~~^
        err, dialect, engine
        ^^^^^^^^^^^^^^^^^^^^
    )
    ^
  File "D:\BudgetTracker_Backend\.venv\Lib\site-packages\sqlalchemy\engine\base.py", line 2440, in _handle_dbapi_exception_noconnection
    raise sqlalchemy_exception.with_traceback(exc_info[2]) from e
  File "D:\BudgetTracker_Backend\.venv\Lib\site-packages\sqlalchemy\engine\base.py", line 143, in __init__
    self._dbapi_connection = engine.raw_connection()
                             ~~~~~~~~~~~~~~~~~~~~~^^
  File "D:\BudgetTracker_Backend\.venv\Lib\site-packages\sqlalchemy\engine\base.py", line 3301, in raw_connection
    return self.pool.connect()
           ~~~~~~~~~~~~~~~~~^^
  File "D:\BudgetTracker_Backend\.venv\Lib\site-packages\sqlalchemy\pool\base.py", line 447, in connect
    return _ConnectionFairy._checkout(self)
           ~~~~~~~~~~~~~~~~~~~~~~~~~~^^^^^^
  File "D:\BudgetTracker_Backend\.venv\Lib\site-packages\sqlalchemy\pool\base.py", line 1264, in _checkout
    fairy = _ConnectionRecord.checkout(pool)
  File "D:\BudgetTracker_Backend\.venv\Lib\site-packages\sqlalchemy\pool\base.py", line 711, in checkout
    rec = pool._do_get()
  File "D:\BudgetTracker_Backend\.venv\Lib\site-packages\sqlalchemy\pool\impl.py", line 177, in _do_get
    with util.safe_reraise():
         ~~~~~~~~~~~~~~~~~^^
  File "D:\BudgetTracker_Backend\.venv\Lib\site-packages\sqlalchemy\util\langhelpers.py", line 224, in __exit__
    raise exc_value.with_traceback(exc_tb)
  File "D:\BudgetTracker_Backend\.venv\Lib\site-packages\sqlalchemy\pool\impl.py", line 175, in _do_get
    return self._create_connection()
           ~~~~~~~~~~~~~~~~~~~~~~~^^
  File "D:\BudgetTracker_Backend\.venv\Lib\site-packages\sqlalchemy\pool\base.py", line 388, in _create_connection
    return _ConnectionRecord(self)
  File "D:\BudgetTracker_Backend\.venv\Lib\site-packages\sqlalchemy\pool\base.py", line 673, in __init__
    self.__connect()
    ~~~~~~~~~~~~~~^^
  File "D:\BudgetTracker_Backend\.venv\Lib\site-packages\sqlalchemy\pool\base.py", line 899, in __connect
    with util.safe_reraise():
         ~~~~~~~~~~~~~~~~~^^
  File "D:\BudgetTracker_Backend\.venv\Lib\site-packages\sqlalchemy\util\langhelpers.py", line 224, in __exit__
    raise exc_value.with_traceback(exc_tb)
  File "D:\BudgetTracker_Backend\.venv\Lib\site-packages\sqlalchemy\pool\base.py", line 895, in __connect
    self.dbapi_connection = connection = pool._invoke_creator(self)
                                         ~~~~~~~~~~~~~~~~~~~~^^^^^^
  File "D:\BudgetTracker_Backend\.venv\Lib\site-packages\sqlalchemy\engine\create.py", line 661, in connect
    return dialect.connect(*cargs, **cparams)
           ~~~~~~~~~~~~~~~^^^^^^^^^^^^^^^^^^^
  File "D:\BudgetTracker_Backend\.venv\Lib\site-packages\sqlalchemy\engine\default.py", line 629, in connect
    return self.loaded_dbapi.connect(*cargs, **cparams)  # type: ignore[no-any-return]  # NOQA: E501
           ~~~~~~~~~~~~~~~~~~~~~~~~~^^^^^^^^^^^^^^^^^^^
  File "D:\BudgetTracker_Backend\.venv\Lib\site-packages\psycopg2\__init__.py", line 135, in connect
    conn = _connect(dsn, connection_factory=connection_factory, **kwasync)
sqlalchemy.exc.OperationalError: (psycopg2.OperationalError) connection to server at "localhost" (::1), port 5432 failed: FATAL:  database "budgettracker" does not exist

(Background on this error at: https://sqlalche.me/e/20/e3q8)
2025-09-19 18:39:12,799 [ERROR] app: ❌ Error in /auth/login: (psycopg2.OperationalError) connection to server at "localhost" (::1), port 5432 failed: FATAL:  database "budgettracker" does not exist

(Background on this error at: https://sqlalche.me/e/20/e3q8)
Traceback (most recent call last):
  File "D:\BudgetTracker_Backend\.venv\Lib\site-packages\sqlalchemy\engine\base.py", line 143, in __init__
    self._dbapi_connection = engine.raw_connection()
                             ~~~~~~~~~~~~~~~~~~~~~^^
  File "D:\BudgetTracker_Backend\.venv\Lib\site-packages\sqlalchemy\engine\base.py", line 3301, in raw_connection
    return self.pool.connect()
           ~~~~~~~~~~~~~~~~~^^
  File "D:\BudgetTracker_Backend\.venv\Lib\site-packages\sqlalchemy\pool\base.py", line 447, in connect
    return _ConnectionFairy._checkout(self)
           ~~~~~~~~~~~~~~~~~~~~~~~~~~^^^^^^
  File "D:\BudgetTracker_Backend\.venv\Lib\site-packages\sqlalchemy\pool\base.py", line 1264, in _checkout
    fairy = _ConnectionRecord.checkout(pool)
  File "D:\BudgetTracker_Backend\.venv\Lib\site-packages\sqlalchemy\pool\base.py", line 711, in checkout
    rec = pool._do_get()
  File "D:\BudgetTracker_Backend\.venv\Lib\site-packages\sqlalchemy\pool\impl.py", line 177, in _do_get
    with util.safe_reraise():
         ~~~~~~~~~~~~~~~~~^^
  File "D:\BudgetTracker_Backend\.venv\Lib\site-packages\sqlalchemy\util\langhelpers.py", line 224, in __exit__
    raise exc_value.with_traceback(exc_tb)
  File "D:\BudgetTracker_Backend\.venv\Lib\site-packages\sqlalchemy\pool\impl.py", line 175, in _do_get
    return self._create_connection()
           ~~~~~~~~~~~~~~~~~~~~~~~^^
  File "D:\BudgetTracker_Backend\.venv\Lib\site-packages\sqlalchemy\pool\base.py", line 388, in _create_connection
    return _ConnectionRecord(self)
  File "D:\BudgetTracker_Backend\.venv\Lib\site-packages\sqlalchemy\pool\base.py", line 673, in __init__
    self.__connect()
    ~~~~~~~~~~~~~~^^
  File "D:\BudgetTracker_Backend\.venv\Lib\site-packages\sqlalchemy\pool\base.py", line 899, in __connect
    with util.safe_reraise():
         ~~~~~~~~~~~~~~~~~^^
  File "D:\BudgetTracker_Backend\.venv\Lib\site-packages\sqlalchemy\util\langhelpers.py", line 224, in __exit__
    raise exc_value.with_traceback(exc_tb)
  File "D:\BudgetTracker_Backend\.venv\Lib\site-packages\sqlalchemy\pool\base.py", line 895, in __connect
    self.dbapi_connection = connection = pool._invoke_creator(self)
                                         ~~~~~~~~~~~~~~~~~~~~^^^^^^
  File "D:\BudgetTracker_Backend\.venv\Lib\site-packages\sqlalchemy\engine\create.py", line 661, in connect
    return dialect.connect(*cargs, **cparams)
           ~~~~~~~~~~~~~~~^^^^^^^^^^^^^^^^^^^
  File "D:\BudgetTracker_Backend\.venv\Lib\site-packages\sqlalchemy\engine\default.py", line 629, in connect
    return self.loaded_dbapi.connect(*cargs, **cparams)  # type: ignore[no-any-return]  # NOQA: E501
           ~~~~~~~~~~~~~~~~~~~~~~~~~^^^^^^^^^^^^^^^^^^^
  File "D:\BudgetTracker_Backend\.venv\Lib\site-packages\psycopg2\__init__.py", line 135, in connect
    conn = _connect(dsn, connection_factory=connection_factory, **kwasync)
psycopg2.OperationalError: connection to server at "localhost" (::1), port 5432 failed: FATAL:  database "budgettracker" does not exist


The above exception was the direct cause of the following exception:

Traceback (most recent call last):
  File "D:\BudgetTracker_Backend\routes\auth_routes.py", line 133, in login
    user = User.query.filter_by(email=email).first()
  File "D:\BudgetTracker_Backend\.venv\Lib\site-packages\sqlalchemy\orm\query.py", line 2759, in first
    return self.limit(1)._iter().first()  # type: ignore
           ~~~~~~~~~~~~~~~~~~~^^
  File "D:\BudgetTracker_Backend\.venv\Lib\site-packages\sqlalchemy\orm\query.py", line 2857, in _iter
    result: Union[ScalarResult[_T], Result[_T]] = self.session.execute(
                                                  ~~~~~~~~~~~~~~~~~~~~^
        statement,
        ^^^^^^^^^^
        params,
        ^^^^^^^
        execution_options={"_sa_orm_load_options": self.load_options},
        ^^^^^^^^^^^^^^^^^^^^^^^^^^^^^^^^^^^^^^^^^^^^^^^^^^^^^^^^^^^^^^
    )
    ^
  File "D:\BudgetTracker_Backend\.venv\Lib\site-packages\sqlalchemy\orm\session.py", line 2365, in execute
    return self._execute_internal(
           ~~~~~~~~~~~~~~~~~~~~~~^
        statement,
        ^^^^^^^^^^
    ...<4 lines>...
        _add_event=_add_event,
        ^^^^^^^^^^^^^^^^^^^^^^
    )
    ^
  File "D:\BudgetTracker_Backend\.venv\Lib\site-packages\sqlalchemy\orm\session.py", line 2241, in _execute_internal
    conn = self._connection_for_bind(bind)
  File "D:\BudgetTracker_Backend\.venv\Lib\site-packages\sqlalchemy\orm\session.py", line 2110, in _connection_for_bind
    return trans._connection_for_bind(engine, execution_options)
           ~~~~~~~~~~~~~~~~~~~~~~~~~~^^^^^^^^^^^^^^^^^^^^^^^^^^^
  File "<string>", line 2, in _connection_for_bind
  File "D:\BudgetTracker_Backend\.venv\Lib\site-packages\sqlalchemy\orm\state_changes.py", line 137, in _go
    ret_value = fn(self, *arg, **kw)
  File "D:\BudgetTracker_Backend\.venv\Lib\site-packages\sqlalchemy\orm\session.py", line 1189, in _connection_for_bind
    conn = bind.connect()
  File "D:\BudgetTracker_Backend\.venv\Lib\site-packages\sqlalchemy\engine\base.py", line 3277, in connect
    return self._connection_cls(self)
           ~~~~~~~~~~~~~~~~~~~~^^^^^^
  File "D:\BudgetTracker_Backend\.venv\Lib\site-packages\sqlalchemy\engine\base.py", line 145, in __init__
    Connection._handle_dbapi_exception_noconnection(
    ~~~~~~~~~~~~~~~~~~~~~~~~~~~~~~~~~~~~~~~~~~~~~~~^
        err, dialect, engine
        ^^^^^^^^^^^^^^^^^^^^
    )
    ^
  File "D:\BudgetTracker_Backend\.venv\Lib\site-packages\sqlalchemy\engine\base.py", line 2440, in _handle_dbapi_exception_noconnection
    raise sqlalchemy_exception.with_traceback(exc_info[2]) from e
  File "D:\BudgetTracker_Backend\.venv\Lib\site-packages\sqlalchemy\engine\base.py", line 143, in __init__
    self._dbapi_connection = engine.raw_connection()
                             ~~~~~~~~~~~~~~~~~~~~~^^
  File "D:\BudgetTracker_Backend\.venv\Lib\site-packages\sqlalchemy\engine\base.py", line 3301, in raw_connection
    return self.pool.connect()
           ~~~~~~~~~~~~~~~~~^^
  File "D:\BudgetTracker_Backend\.venv\Lib\site-packages\sqlalchemy\pool\base.py", line 447, in connect
    return _ConnectionFairy._checkout(self)
           ~~~~~~~~~~~~~~~~~~~~~~~~~~^^^^^^
  File "D:\BudgetTracker_Backend\.venv\Lib\site-packages\sqlalchemy\pool\base.py", line 1264, in _checkout
    fairy = _ConnectionRecord.checkout(pool)
  File "D:\BudgetTracker_Backend\.venv\Lib\site-packages\sqlalchemy\pool\base.py", line 711, in checkout
    rec = pool._do_get()
  File "D:\BudgetTracker_Backend\.venv\Lib\site-packages\sqlalchemy\pool\impl.py", line 177, in _do_get
    with util.safe_reraise():
         ~~~~~~~~~~~~~~~~~^^
  File "D:\BudgetTracker_Backend\.venv\Lib\site-packages\sqlalchemy\util\langhelpers.py", line 224, in __exit__
    raise exc_value.with_traceback(exc_tb)
  File "D:\BudgetTracker_Backend\.venv\Lib\site-packages\sqlalchemy\pool\impl.py", line 175, in _do_get
    return self._create_connection()
           ~~~~~~~~~~~~~~~~~~~~~~~^^
  File "D:\BudgetTracker_Backend\.venv\Lib\site-packages\sqlalchemy\pool\base.py", line 388, in _create_connection
    return _ConnectionRecord(self)
  File "D:\BudgetTracker_Backend\.venv\Lib\site-packages\sqlalchemy\pool\base.py", line 673, in __init__
    self.__connect()
    ~~~~~~~~~~~~~~^^
  File "D:\BudgetTracker_Backend\.venv\Lib\site-packages\sqlalchemy\pool\base.py", line 899, in __connect
    with util.safe_reraise():
         ~~~~~~~~~~~~~~~~~^^
  File "D:\BudgetTracker_Backend\.venv\Lib\site-packages\sqlalchemy\util\langhelpers.py", line 224, in __exit__
    raise exc_value.with_traceback(exc_tb)
  File "D:\BudgetTracker_Backend\.venv\Lib\site-packages\sqlalchemy\pool\base.py", line 895, in __connect
    self.dbapi_connection = connection = pool._invoke_creator(self)
                                         ~~~~~~~~~~~~~~~~~~~~^^^^^^
  File "D:\BudgetTracker_Backend\.venv\Lib\site-packages\sqlalchemy\engine\create.py", line 661, in connect
    return dialect.connect(*cargs, **cparams)
           ~~~~~~~~~~~~~~~^^^^^^^^^^^^^^^^^^^
  File "D:\BudgetTracker_Backend\.venv\Lib\site-packages\sqlalchemy\engine\default.py", line 629, in connect
    return self.loaded_dbapi.connect(*cargs, **cparams)  # type: ignore[no-any-return]  # NOQA: E501
           ~~~~~~~~~~~~~~~~~~~~~~~~~^^^^^^^^^^^^^^^^^^^
  File "D:\BudgetTracker_Backend\.venv\Lib\site-packages\psycopg2\__init__.py", line 135, in connect
    conn = _connect(dsn, connection_factory=connection_factory, **kwasync)
sqlalchemy.exc.OperationalError: (psycopg2.OperationalError) connection to server at "localhost" (::1), port 5432 failed: FATAL:  database "budgettracker" does not exist

(Background on this error at: https://sqlalche.me/e/20/e3q8)
2025-09-19 18:39:13,117 [ERROR] app: ❌ Error in /auth/login: (psycopg2.OperationalError) connection to server at "localhost" (::1), port 5432 failed: FATAL:  database "budgettracker" does not exist

(Background on this error at: https://sqlalche.me/e/20/e3q8)
Traceback (most recent call last):
  File "D:\BudgetTracker_Backend\.venv\Lib\site-packages\sqlalchemy\engine\base.py", line 143, in __init__
    self._dbapi_connection = engine.raw_connection()
                             ~~~~~~~~~~~~~~~~~~~~~^^
  File "D:\BudgetTracker_Backend\.venv\Lib\site-packages\sqlalchemy\engine\base.py", line 3301, in raw_connection
    return self.pool.connect()
           ~~~~~~~~~~~~~~~~~^^
  File "D:\BudgetTracker_Backend\.venv\Lib\site-packages\sqlalchemy\pool\base.py", line 447, in connect
    return _ConnectionFairy._checkout(self)
           ~~~~~~~~~~~~~~~~~~~~~~~~~~^^^^^^
  File "D:\BudgetTracker_Backend\.venv\Lib\site-packages\sqlalchemy\pool\base.py", line 1264, in _checkout
    fairy = _ConnectionRecord.checkout(pool)
  File "D:\BudgetTracker_Backend\.venv\Lib\site-packages\sqlalchemy\pool\base.py", line 711, in checkout
    rec = pool._do_get()
  File "D:\BudgetTracker_Backend\.venv\Lib\site-packages\sqlalchemy\pool\impl.py", line 177, in _do_get
    with util.safe_reraise():
         ~~~~~~~~~~~~~~~~~^^
  File "D:\BudgetTracker_Backend\.venv\Lib\site-packages\sqlalchemy\util\langhelpers.py", line 224, in __exit__
    raise exc_value.with_traceback(exc_tb)
  File "D:\BudgetTracker_Backend\.venv\Lib\site-packages\sqlalchemy\pool\impl.py", line 175, in _do_get
    return self._create_connection()
           ~~~~~~~~~~~~~~~~~~~~~~~^^
  File "D:\BudgetTracker_Backend\.venv\Lib\site-packages\sqlalchemy\pool\base.py", line 388, in _create_connection
    return _ConnectionRecord(self)
  File "D:\BudgetTracker_Backend\.venv\Lib\site-packages\sqlalchemy\pool\base.py", line 673, in __init__
    self.__connect()
    ~~~~~~~~~~~~~~^^
  File "D:\BudgetTracker_Backend\.venv\Lib\site-packages\sqlalchemy\pool\base.py", line 899, in __connect
    with util.safe_reraise():
         ~~~~~~~~~~~~~~~~~^^
  File "D:\BudgetTracker_Backend\.venv\Lib\site-packages\sqlalchemy\util\langhelpers.py", line 224, in __exit__
    raise exc_value.with_traceback(exc_tb)
  File "D:\BudgetTracker_Backend\.venv\Lib\site-packages\sqlalchemy\pool\base.py", line 895, in __connect
    self.dbapi_connection = connection = pool._invoke_creator(self)
                                         ~~~~~~~~~~~~~~~~~~~~^^^^^^
  File "D:\BudgetTracker_Backend\.venv\Lib\site-packages\sqlalchemy\engine\create.py", line 661, in connect
    return dialect.connect(*cargs, **cparams)
           ~~~~~~~~~~~~~~~^^^^^^^^^^^^^^^^^^^
  File "D:\BudgetTracker_Backend\.venv\Lib\site-packages\sqlalchemy\engine\default.py", line 629, in connect
    return self.loaded_dbapi.connect(*cargs, **cparams)  # type: ignore[no-any-return]  # NOQA: E501
           ~~~~~~~~~~~~~~~~~~~~~~~~~^^^^^^^^^^^^^^^^^^^
  File "D:\BudgetTracker_Backend\.venv\Lib\site-packages\psycopg2\__init__.py", line 135, in connect
    conn = _connect(dsn, connection_factory=connection_factory, **kwasync)
psycopg2.OperationalError: connection to server at "localhost" (::1), port 5432 failed: FATAL:  database "budgettracker" does not exist


The above exception was the direct cause of the following exception:

Traceback (most recent call last):
  File "D:\BudgetTracker_Backend\routes\auth_routes.py", line 133, in login
    user = User.query.filter_by(email=email).first()
  File "D:\BudgetTracker_Backend\.venv\Lib\site-packages\sqlalchemy\orm\query.py", line 2759, in first
    return self.limit(1)._iter().first()  # type: ignore
           ~~~~~~~~~~~~~~~~~~~^^
  File "D:\BudgetTracker_Backend\.venv\Lib\site-packages\sqlalchemy\orm\query.py", line 2857, in _iter
    result: Union[ScalarResult[_T], Result[_T]] = self.session.execute(
                                                  ~~~~~~~~~~~~~~~~~~~~^
        statement,
        ^^^^^^^^^^
        params,
        ^^^^^^^
        execution_options={"_sa_orm_load_options": self.load_options},
        ^^^^^^^^^^^^^^^^^^^^^^^^^^^^^^^^^^^^^^^^^^^^^^^^^^^^^^^^^^^^^^
    )
    ^
  File "D:\BudgetTracker_Backend\.venv\Lib\site-packages\sqlalchemy\orm\session.py", line 2365, in execute
    return self._execute_internal(
           ~~~~~~~~~~~~~~~~~~~~~~^
        statement,
        ^^^^^^^^^^
    ...<4 lines>...
        _add_event=_add_event,
        ^^^^^^^^^^^^^^^^^^^^^^
    )
    ^
  File "D:\BudgetTracker_Backend\.venv\Lib\site-packages\sqlalchemy\orm\session.py", line 2241, in _execute_internal
    conn = self._connection_for_bind(bind)
  File "D:\BudgetTracker_Backend\.venv\Lib\site-packages\sqlalchemy\orm\session.py", line 2110, in _connection_for_bind
    return trans._connection_for_bind(engine, execution_options)
           ~~~~~~~~~~~~~~~~~~~~~~~~~~^^^^^^^^^^^^^^^^^^^^^^^^^^^
  File "<string>", line 2, in _connection_for_bind
  File "D:\BudgetTracker_Backend\.venv\Lib\site-packages\sqlalchemy\orm\state_changes.py", line 137, in _go
    ret_value = fn(self, *arg, **kw)
  File "D:\BudgetTracker_Backend\.venv\Lib\site-packages\sqlalchemy\orm\session.py", line 1189, in _connection_for_bind
    conn = bind.connect()
  File "D:\BudgetTracker_Backend\.venv\Lib\site-packages\sqlalchemy\engine\base.py", line 3277, in connect
    return self._connection_cls(self)
           ~~~~~~~~~~~~~~~~~~~~^^^^^^
  File "D:\BudgetTracker_Backend\.venv\Lib\site-packages\sqlalchemy\engine\base.py", line 145, in __init__
    Connection._handle_dbapi_exception_noconnection(
    ~~~~~~~~~~~~~~~~~~~~~~~~~~~~~~~~~~~~~~~~~~~~~~~^
        err, dialect, engine
        ^^^^^^^^^^^^^^^^^^^^
    )
    ^
  File "D:\BudgetTracker_Backend\.venv\Lib\site-packages\sqlalchemy\engine\base.py", line 2440, in _handle_dbapi_exception_noconnection
    raise sqlalchemy_exception.with_traceback(exc_info[2]) from e
  File "D:\BudgetTracker_Backend\.venv\Lib\site-packages\sqlalchemy\engine\base.py", line 143, in __init__
    self._dbapi_connection = engine.raw_connection()
                             ~~~~~~~~~~~~~~~~~~~~~^^
  File "D:\BudgetTracker_Backend\.venv\Lib\site-packages\sqlalchemy\engine\base.py", line 3301, in raw_connection
    return self.pool.connect()
           ~~~~~~~~~~~~~~~~~^^
  File "D:\BudgetTracker_Backend\.venv\Lib\site-packages\sqlalchemy\pool\base.py", line 447, in connect
    return _ConnectionFairy._checkout(self)
           ~~~~~~~~~~~~~~~~~~~~~~~~~~^^^^^^
  File "D:\BudgetTracker_Backend\.venv\Lib\site-packages\sqlalchemy\pool\base.py", line 1264, in _checkout
    fairy = _ConnectionRecord.checkout(pool)
  File "D:\BudgetTracker_Backend\.venv\Lib\site-packages\sqlalchemy\pool\base.py", line 711, in checkout
    rec = pool._do_get()
  File "D:\BudgetTracker_Backend\.venv\Lib\site-packages\sqlalchemy\pool\impl.py", line 177, in _do_get
    with util.safe_reraise():
         ~~~~~~~~~~~~~~~~~^^
  File "D:\BudgetTracker_Backend\.venv\Lib\site-packages\sqlalchemy\util\langhelpers.py", line 224, in __exit__
    raise exc_value.with_traceback(exc_tb)
  File "D:\BudgetTracker_Backend\.venv\Lib\site-packages\sqlalchemy\pool\impl.py", line 175, in _do_get
    return self._create_connection()
           ~~~~~~~~~~~~~~~~~~~~~~~^^
  File "D:\BudgetTracker_Backend\.venv\Lib\site-packages\sqlalchemy\pool\base.py", line 388, in _create_connection
    return _ConnectionRecord(self)
  File "D:\BudgetTracker_Backend\.venv\Lib\site-packages\sqlalchemy\pool\base.py", line 673, in __init__
    self.__connect()
    ~~~~~~~~~~~~~~^^
  File "D:\BudgetTracker_Backend\.venv\Lib\site-packages\sqlalchemy\pool\base.py", line 899, in __connect
    with util.safe_reraise():
         ~~~~~~~~~~~~~~~~~^^
  File "D:\BudgetTracker_Backend\.venv\Lib\site-packages\sqlalchemy\util\langhelpers.py", line 224, in __exit__
    raise exc_value.with_traceback(exc_tb)
  File "D:\BudgetTracker_Backend\.venv\Lib\site-packages\sqlalchemy\pool\base.py", line 895, in __connect
    self.dbapi_connection = connection = pool._invoke_creator(self)
                                         ~~~~~~~~~~~~~~~~~~~~^^^^^^
  File "D:\BudgetTracker_Backend\.venv\Lib\site-packages\sqlalchemy\engine\create.py", line 661, in connect
    return dialect.connect(*cargs, **cparams)
           ~~~~~~~~~~~~~~~^^^^^^^^^^^^^^^^^^^
  File "D:\BudgetTracker_Backend\.venv\Lib\site-packages\sqlalchemy\engine\default.py", line 629, in connect
    return self.loaded_dbapi.connect(*cargs, **cparams)  # type: ignore[no-any-return]  # NOQA: E501
           ~~~~~~~~~~~~~~~~~~~~~~~~~^^^^^^^^^^^^^^^^^^^
  File "D:\BudgetTracker_Backend\.venv\Lib\site-packages\psycopg2\__init__.py", line 135, in connect
    conn = _connect(dsn, connection_factory=connection_factory, **kwasync)
sqlalchemy.exc.OperationalError: (psycopg2.OperationalError) connection to server at "localhost" (::1), port 5432 failed: FATAL:  database "budgettracker" does not exist

(Background on this error at: https://sqlalche.me/e/20/e3q8)
2025-09-19 18:39:13,332 [ERROR] app: ❌ Error in /auth/login: (psycopg2.OperationalError) connection to server at "localhost" (::1), port 5432 failed: FATAL:  database "budgettracker" does not exist

(Background on this error at: https://sqlalche.me/e/20/e3q8)
Traceback (most recent call last):
  File "D:\BudgetTracker_Backend\.venv\Lib\site-packages\sqlalchemy\engine\base.py", line 143, in __init__
    self._dbapi_connection = engine.raw_connection()
                             ~~~~~~~~~~~~~~~~~~~~~^^
  File "D:\BudgetTracker_Backend\.venv\Lib\site-packages\sqlalchemy\engine\base.py", line 3301, in raw_connection
    return self.pool.connect()
           ~~~~~~~~~~~~~~~~~^^
  File "D:\BudgetTracker_Backend\.venv\Lib\site-packages\sqlalchemy\pool\base.py", line 447, in connect
    return _ConnectionFairy._checkout(self)
           ~~~~~~~~~~~~~~~~~~~~~~~~~~^^^^^^
  File "D:\BudgetTracker_Backend\.venv\Lib\site-packages\sqlalchemy\pool\base.py", line 1264, in _checkout
    fairy = _ConnectionRecord.checkout(pool)
  File "D:\BudgetTracker_Backend\.venv\Lib\site-packages\sqlalchemy\pool\base.py", line 711, in checkout
    rec = pool._do_get()
  File "D:\BudgetTracker_Backend\.venv\Lib\site-packages\sqlalchemy\pool\impl.py", line 177, in _do_get
    with util.safe_reraise():
         ~~~~~~~~~~~~~~~~~^^
  File "D:\BudgetTracker_Backend\.venv\Lib\site-packages\sqlalchemy\util\langhelpers.py", line 224, in __exit__
    raise exc_value.with_traceback(exc_tb)
  File "D:\BudgetTracker_Backend\.venv\Lib\site-packages\sqlalchemy\pool\impl.py", line 175, in _do_get
    return self._create_connection()
           ~~~~~~~~~~~~~~~~~~~~~~~^^
  File "D:\BudgetTracker_Backend\.venv\Lib\site-packages\sqlalchemy\pool\base.py", line 388, in _create_connection
    return _ConnectionRecord(self)
  File "D:\BudgetTracker_Backend\.venv\Lib\site-packages\sqlalchemy\pool\base.py", line 673, in __init__
    self.__connect()
    ~~~~~~~~~~~~~~^^
  File "D:\BudgetTracker_Backend\.venv\Lib\site-packages\sqlalchemy\pool\base.py", line 899, in __connect
    with util.safe_reraise():
         ~~~~~~~~~~~~~~~~~^^
  File "D:\BudgetTracker_Backend\.venv\Lib\site-packages\sqlalchemy\util\langhelpers.py", line 224, in __exit__
    raise exc_value.with_traceback(exc_tb)
  File "D:\BudgetTracker_Backend\.venv\Lib\site-packages\sqlalchemy\pool\base.py", line 895, in __connect
    self.dbapi_connection = connection = pool._invoke_creator(self)
                                         ~~~~~~~~~~~~~~~~~~~~^^^^^^
  File "D:\BudgetTracker_Backend\.venv\Lib\site-packages\sqlalchemy\engine\create.py", line 661, in connect
    return dialect.connect(*cargs, **cparams)
           ~~~~~~~~~~~~~~~^^^^^^^^^^^^^^^^^^^
  File "D:\BudgetTracker_Backend\.venv\Lib\site-packages\sqlalchemy\engine\default.py", line 629, in connect
    return self.loaded_dbapi.connect(*cargs, **cparams)  # type: ignore[no-any-return]  # NOQA: E501
           ~~~~~~~~~~~~~~~~~~~~~~~~~^^^^^^^^^^^^^^^^^^^
  File "D:\BudgetTracker_Backend\.venv\Lib\site-packages\psycopg2\__init__.py", line 135, in connect
    conn = _connect(dsn, connection_factory=connection_factory, **kwasync)
psycopg2.OperationalError: connection to server at "localhost" (::1), port 5432 failed: FATAL:  database "budgettracker" does not exist


The above exception was the direct cause of the following exception:

Traceback (most recent call last):
  File "D:\BudgetTracker_Backend\routes\auth_routes.py", line 133, in login
    user = User.query.filter_by(email=email).first()
  File "D:\BudgetTracker_Backend\.venv\Lib\site-packages\sqlalchemy\orm\query.py", line 2759, in first
    return self.limit(1)._iter().first()  # type: ignore
           ~~~~~~~~~~~~~~~~~~~^^
  File "D:\BudgetTracker_Backend\.venv\Lib\site-packages\sqlalchemy\orm\query.py", line 2857, in _iter
    result: Union[ScalarResult[_T], Result[_T]] = self.session.execute(
                                                  ~~~~~~~~~~~~~~~~~~~~^
        statement,
        ^^^^^^^^^^
        params,
        ^^^^^^^
        execution_options={"_sa_orm_load_options": self.load_options},
        ^^^^^^^^^^^^^^^^^^^^^^^^^^^^^^^^^^^^^^^^^^^^^^^^^^^^^^^^^^^^^^
    )
    ^
  File "D:\BudgetTracker_Backend\.venv\Lib\site-packages\sqlalchemy\orm\session.py", line 2365, in execute
    return self._execute_internal(
           ~~~~~~~~~~~~~~~~~~~~~~^
        statement,
        ^^^^^^^^^^
    ...<4 lines>...
        _add_event=_add_event,
        ^^^^^^^^^^^^^^^^^^^^^^
    )
    ^
  File "D:\BudgetTracker_Backend\.venv\Lib\site-packages\sqlalchemy\orm\session.py", line 2241, in _execute_internal
    conn = self._connection_for_bind(bind)
  File "D:\BudgetTracker_Backend\.venv\Lib\site-packages\sqlalchemy\orm\session.py", line 2110, in _connection_for_bind
    return trans._connection_for_bind(engine, execution_options)
           ~~~~~~~~~~~~~~~~~~~~~~~~~~^^^^^^^^^^^^^^^^^^^^^^^^^^^
  File "<string>", line 2, in _connection_for_bind
  File "D:\BudgetTracker_Backend\.venv\Lib\site-packages\sqlalchemy\orm\state_changes.py", line 137, in _go
    ret_value = fn(self, *arg, **kw)
  File "D:\BudgetTracker_Backend\.venv\Lib\site-packages\sqlalchemy\orm\session.py", line 1189, in _connection_for_bind
    conn = bind.connect()
  File "D:\BudgetTracker_Backend\.venv\Lib\site-packages\sqlalchemy\engine\base.py", line 3277, in connect
    return self._connection_cls(self)
           ~~~~~~~~~~~~~~~~~~~~^^^^^^
  File "D:\BudgetTracker_Backend\.venv\Lib\site-packages\sqlalchemy\engine\base.py", line 145, in __init__
    Connection._handle_dbapi_exception_noconnection(
    ~~~~~~~~~~~~~~~~~~~~~~~~~~~~~~~~~~~~~~~~~~~~~~~^
        err, dialect, engine
        ^^^^^^^^^^^^^^^^^^^^
    )
    ^
  File "D:\BudgetTracker_Backend\.venv\Lib\site-packages\sqlalchemy\engine\base.py", line 2440, in _handle_dbapi_exception_noconnection
    raise sqlalchemy_exception.with_traceback(exc_info[2]) from e
  File "D:\BudgetTracker_Backend\.venv\Lib\site-packages\sqlalchemy\engine\base.py", line 143, in __init__
    self._dbapi_connection = engine.raw_connection()
                             ~~~~~~~~~~~~~~~~~~~~~^^
  File "D:\BudgetTracker_Backend\.venv\Lib\site-packages\sqlalchemy\engine\base.py", line 3301, in raw_connection
    return self.pool.connect()
           ~~~~~~~~~~~~~~~~~^^
  File "D:\BudgetTracker_Backend\.venv\Lib\site-packages\sqlalchemy\pool\base.py", line 447, in connect
    return _ConnectionFairy._checkout(self)
           ~~~~~~~~~~~~~~~~~~~~~~~~~~^^^^^^
  File "D:\BudgetTracker_Backend\.venv\Lib\site-packages\sqlalchemy\pool\base.py", line 1264, in _checkout
    fairy = _ConnectionRecord.checkout(pool)
  File "D:\BudgetTracker_Backend\.venv\Lib\site-packages\sqlalchemy\pool\base.py", line 711, in checkout
    rec = pool._do_get()
  File "D:\BudgetTracker_Backend\.venv\Lib\site-packages\sqlalchemy\pool\impl.py", line 177, in _do_get
    with util.safe_reraise():
         ~~~~~~~~~~~~~~~~~^^
  File "D:\BudgetTracker_Backend\.venv\Lib\site-packages\sqlalchemy\util\langhelpers.py", line 224, in __exit__
    raise exc_value.with_traceback(exc_tb)
  File "D:\BudgetTracker_Backend\.venv\Lib\site-packages\sqlalchemy\pool\impl.py", line 175, in _do_get
    return self._create_connection()
           ~~~~~~~~~~~~~~~~~~~~~~~^^
  File "D:\BudgetTracker_Backend\.venv\Lib\site-packages\sqlalchemy\pool\base.py", line 388, in _create_connection
    return _ConnectionRecord(self)
  File "D:\BudgetTracker_Backend\.venv\Lib\site-packages\sqlalchemy\pool\base.py", line 673, in __init__
    self.__connect()
    ~~~~~~~~~~~~~~^^
  File "D:\BudgetTracker_Backend\.venv\Lib\site-packages\sqlalchemy\pool\base.py", line 899, in __connect
    with util.safe_reraise():
         ~~~~~~~~~~~~~~~~~^^
  File "D:\BudgetTracker_Backend\.venv\Lib\site-packages\sqlalchemy\util\langhelpers.py", line 224, in __exit__
    raise exc_value.with_traceback(exc_tb)
  File "D:\BudgetTracker_Backend\.venv\Lib\site-packages\sqlalchemy\pool\base.py", line 895, in __connect
    self.dbapi_connection = connection = pool._invoke_creator(self)
                                         ~~~~~~~~~~~~~~~~~~~~^^^^^^
  File "D:\BudgetTracker_Backend\.venv\Lib\site-packages\sqlalchemy\engine\create.py", line 661, in connect
    return dialect.connect(*cargs, **cparams)
           ~~~~~~~~~~~~~~~^^^^^^^^^^^^^^^^^^^
  File "D:\BudgetTracker_Backend\.venv\Lib\site-packages\sqlalchemy\engine\default.py", line 629, in connect
    return self.loaded_dbapi.connect(*cargs, **cparams)  # type: ignore[no-any-return]  # NOQA: E501
           ~~~~~~~~~~~~~~~~~~~~~~~~~^^^^^^^^^^^^^^^^^^^
  File "D:\BudgetTracker_Backend\.venv\Lib\site-packages\psycopg2\__init__.py", line 135, in connect
    conn = _connect(dsn, connection_factory=connection_factory, **kwasync)
sqlalchemy.exc.OperationalError: (psycopg2.OperationalError) connection to server at "localhost" (::1), port 5432 failed: FATAL:  database "budgettracker" does not exist

(Background on this error at: https://sqlalche.me/e/20/e3q8)
2025-09-19 18:51:53,490 [INFO] app: 📝 Logging configured (level=INFO)
2025-09-19 18:51:53,492 [INFO] app: 🔗 Database URI: postgresql://postgres:****@localhost:5432/budgettracker
2025-09-19 18:51:53,595 [INFO] app: 🌍 CORS enabled for origins: http://localhost:5173, http://127.0.0.1:5173
2025-09-19 18:51:53,606 [INFO] app: 🧩 Blueprints registered: ['auth', 'budget', 'home']
2025-09-19 18:51:53,621 [INFO] app: ⏰ Scheduler started successfully
2025-09-19 18:55:01,435 [INFO] app: 📝 Logging configured (level=DEBUG)
2025-09-19 18:55:01,436 [INFO] app: 🔗 Database URI: postgresql://postgres:****@localhost:5432/budgettracker
2025-09-19 18:55:01,532 [INFO] app: 🌍 CORS enabled for origins: http://localhost:5173, http://127.0.0.1:5173
2025-09-19 18:55:01,540 [INFO] app: 🧩 Blueprints registered: ['auth', 'budget', 'home']
2025-09-19 18:55:01,547 [INFO] app: ⏰ Scheduler started successfully
2025-09-19 18:55:01,548 [INFO] app: 🚀 Starting Budget Tracker API at http://127.0.0.1:5000 (debug=False)
2025-09-20 13:58:29,992 [INFO] app: 📝 Logging configured (level=DEBUG)
2025-09-20 13:58:30,000 [INFO] app: 🔗 Database URI: postgresql://postgres:****@localhost:5432/budgettracker
2025-09-20 13:58:30,285 [INFO] app: 🌍 CORS enabled for origins: http://localhost:5173, http://127.0.0.1:5173
2025-09-20 13:58:30,357 [INFO] app: 🧩 Blueprints registered: ['auth', 'budget', 'home']
2025-09-20 13:58:30,475 [INFO] app: ⏰ Scheduler started successfully
2025-09-20 13:58:30,479 [INFO] app: 🚀 Starting Budget Tracker API at http://127.0.0.1:5000 (debug=False)
2025-09-20 14:12:07,111 [INFO] app: 📝 Logging configured (level=DEBUG)
2025-09-20 14:12:07,115 [INFO] app: 🔗 Database URI: postgresql://postgres:****@localhost:5432/budgettracker
2025-09-20 14:12:07,272 [INFO] app: 🌍 CORS enabled for origins: http://localhost:5173, http://127.0.0.1:5173
2025-09-20 14:12:07,297 [INFO] app: 🧩 Blueprints registered: ['auth', 'budget', 'home']
2025-09-20 14:12:07,329 [INFO] app: ⏰ Scheduler started successfully
2025-09-20 14:12:07,333 [INFO] app: 🚀 Starting Budget Tracker API at http://127.0.0.1:5000 (debug=False)
2025-09-20 14:18:52,533 [INFO] app: 📝 Logging configured (level=DEBUG)
2025-09-20 14:18:52,548 [INFO] app: 🔗 Database URI: postgresql://postgres:****@localhost:5432/budgettracker
2025-09-20 14:18:56,166 [INFO] app: 🌍 CORS enabled for origins: http://localhost:5173, http://127.0.0.1:5173
2025-09-20 14:18:56,304 [INFO] app: 🧩 Blueprints registered: ['auth', 'budget', 'home']
2025-09-20 14:18:56,603 [INFO] app: ⏰ Scheduler started successfully
2025-09-20 14:18:56,763 [INFO] app: 🚀 Starting Budget Tracker API at http://127.0.0.1:5000 (debug=False)
2025-09-20 14:19:18,462 [ERROR] app: ❌ Error in /auth/login: (psycopg2.OperationalError) connection to server at "localhost" (::1), port 5432 failed: FATAL:  password authentication failed for user "postgres"

(Background on this error at: https://sqlalche.me/e/20/e3q8)
Traceback (most recent call last):
  File "C:\Users\Bala\AppData\Roaming\Python\Python313\site-packages\sqlalchemy\engine\base.py", line 143, in __init__
    self._dbapi_connection = engine.raw_connection()
                             ~~~~~~~~~~~~~~~~~~~~~^^
  File "C:\Users\Bala\AppData\Roaming\Python\Python313\site-packages\sqlalchemy\engine\base.py", line 3301, in raw_connection
    return self.pool.connect()
           ~~~~~~~~~~~~~~~~~^^
  File "C:\Users\Bala\AppData\Roaming\Python\Python313\site-packages\sqlalchemy\pool\base.py", line 447, in connect
    return _ConnectionFairy._checkout(self)
           ~~~~~~~~~~~~~~~~~~~~~~~~~~^^^^^^
  File "C:\Users\Bala\AppData\Roaming\Python\Python313\site-packages\sqlalchemy\pool\base.py", line 1264, in _checkout
    fairy = _ConnectionRecord.checkout(pool)
  File "C:\Users\Bala\AppData\Roaming\Python\Python313\site-packages\sqlalchemy\pool\base.py", line 711, in checkout
    rec = pool._do_get()
  File "C:\Users\Bala\AppData\Roaming\Python\Python313\site-packages\sqlalchemy\pool\impl.py", line 177, in _do_get
    with util.safe_reraise():
         ~~~~~~~~~~~~~~~~~^^
  File "C:\Users\Bala\AppData\Roaming\Python\Python313\site-packages\sqlalchemy\util\langhelpers.py", line 224, in __exit__
    raise exc_value.with_traceback(exc_tb)
  File "C:\Users\Bala\AppData\Roaming\Python\Python313\site-packages\sqlalchemy\pool\impl.py", line 175, in _do_get
    return self._create_connection()
           ~~~~~~~~~~~~~~~~~~~~~~~^^
  File "C:\Users\Bala\AppData\Roaming\Python\Python313\site-packages\sqlalchemy\pool\base.py", line 388, in _create_connection
    return _ConnectionRecord(self)
  File "C:\Users\Bala\AppData\Roaming\Python\Python313\site-packages\sqlalchemy\pool\base.py", line 673, in __init__
    self.__connect()
    ~~~~~~~~~~~~~~^^
  File "C:\Users\Bala\AppData\Roaming\Python\Python313\site-packages\sqlalchemy\pool\base.py", line 899, in __connect
    with util.safe_reraise():
         ~~~~~~~~~~~~~~~~~^^
  File "C:\Users\Bala\AppData\Roaming\Python\Python313\site-packages\sqlalchemy\util\langhelpers.py", line 224, in __exit__
    raise exc_value.with_traceback(exc_tb)
  File "C:\Users\Bala\AppData\Roaming\Python\Python313\site-packages\sqlalchemy\pool\base.py", line 895, in __connect
    self.dbapi_connection = connection = pool._invoke_creator(self)
                                         ~~~~~~~~~~~~~~~~~~~~^^^^^^
  File "C:\Users\Bala\AppData\Roaming\Python\Python313\site-packages\sqlalchemy\engine\create.py", line 661, in connect
    return dialect.connect(*cargs, **cparams)
           ~~~~~~~~~~~~~~~^^^^^^^^^^^^^^^^^^^
  File "C:\Users\Bala\AppData\Roaming\Python\Python313\site-packages\sqlalchemy\engine\default.py", line 629, in connect
    return self.loaded_dbapi.connect(*cargs, **cparams)  # type: ignore[no-any-return]  # NOQA: E501
           ~~~~~~~~~~~~~~~~~~~~~~~~~^^^^^^^^^^^^^^^^^^^
  File "C:\Users\Bala\AppData\Roaming\Python\Python313\site-packages\psycopg2\__init__.py", line 135, in connect
    conn = _connect(dsn, connection_factory=connection_factory, **kwasync)
psycopg2.OperationalError: connection to server at "localhost" (::1), port 5432 failed: FATAL:  password authentication failed for user "postgres"


The above exception was the direct cause of the following exception:

Traceback (most recent call last):
  File "D:\AI Budget_Tracker_Backend\BudgetTracker_Backend\routes\auth_routes.py", line 133, in login
    user = User.query.filter_by(email=email).first()
  File "C:\Users\Bala\AppData\Roaming\Python\Python313\site-packages\sqlalchemy\orm\query.py", line 2759, in first
    return self.limit(1)._iter().first()  # type: ignore
           ~~~~~~~~~~~~~~~~~~~^^
  File "C:\Users\Bala\AppData\Roaming\Python\Python313\site-packages\sqlalchemy\orm\query.py", line 2857, in _iter
    result: Union[ScalarResult[_T], Result[_T]] = self.session.execute(
                                                  ~~~~~~~~~~~~~~~~~~~~^
        statement,
        ^^^^^^^^^^
        params,
        ^^^^^^^
        execution_options={"_sa_orm_load_options": self.load_options},
        ^^^^^^^^^^^^^^^^^^^^^^^^^^^^^^^^^^^^^^^^^^^^^^^^^^^^^^^^^^^^^^
    )
    ^
  File "C:\Users\Bala\AppData\Roaming\Python\Python313\site-packages\sqlalchemy\orm\session.py", line 2365, in execute
    return self._execute_internal(
           ~~~~~~~~~~~~~~~~~~~~~~^
        statement,
        ^^^^^^^^^^
    ...<4 lines>...
        _add_event=_add_event,
        ^^^^^^^^^^^^^^^^^^^^^^
    )
    ^
  File "C:\Users\Bala\AppData\Roaming\Python\Python313\site-packages\sqlalchemy\orm\session.py", line 2241, in _execute_internal
    conn = self._connection_for_bind(bind)
  File "C:\Users\Bala\AppData\Roaming\Python\Python313\site-packages\sqlalchemy\orm\session.py", line 2110, in _connection_for_bind
    return trans._connection_for_bind(engine, execution_options)
           ~~~~~~~~~~~~~~~~~~~~~~~~~~^^^^^^^^^^^^^^^^^^^^^^^^^^^
  File "<string>", line 2, in _connection_for_bind
  File "C:\Users\Bala\AppData\Roaming\Python\Python313\site-packages\sqlalchemy\orm\state_changes.py", line 137, in _go
    ret_value = fn(self, *arg, **kw)
  File "C:\Users\Bala\AppData\Roaming\Python\Python313\site-packages\sqlalchemy\orm\session.py", line 1189, in _connection_for_bind
    conn = bind.connect()
  File "C:\Users\Bala\AppData\Roaming\Python\Python313\site-packages\sqlalchemy\engine\base.py", line 3277, in connect
    return self._connection_cls(self)
           ~~~~~~~~~~~~~~~~~~~~^^^^^^
  File "C:\Users\Bala\AppData\Roaming\Python\Python313\site-packages\sqlalchemy\engine\base.py", line 145, in __init__
    Connection._handle_dbapi_exception_noconnection(
    ~~~~~~~~~~~~~~~~~~~~~~~~~~~~~~~~~~~~~~~~~~~~~~~^
        err, dialect, engine
        ^^^^^^^^^^^^^^^^^^^^
    )
    ^
  File "C:\Users\Bala\AppData\Roaming\Python\Python313\site-packages\sqlalchemy\engine\base.py", line 2440, in _handle_dbapi_exception_noconnection
    raise sqlalchemy_exception.with_traceback(exc_info[2]) from e
  File "C:\Users\Bala\AppData\Roaming\Python\Python313\site-packages\sqlalchemy\engine\base.py", line 143, in __init__
    self._dbapi_connection = engine.raw_connection()
                             ~~~~~~~~~~~~~~~~~~~~~^^
  File "C:\Users\Bala\AppData\Roaming\Python\Python313\site-packages\sqlalchemy\engine\base.py", line 3301, in raw_connection
    return self.pool.connect()
           ~~~~~~~~~~~~~~~~~^^
  File "C:\Users\Bala\AppData\Roaming\Python\Python313\site-packages\sqlalchemy\pool\base.py", line 447, in connect
    return _ConnectionFairy._checkout(self)
           ~~~~~~~~~~~~~~~~~~~~~~~~~~^^^^^^
  File "C:\Users\Bala\AppData\Roaming\Python\Python313\site-packages\sqlalchemy\pool\base.py", line 1264, in _checkout
    fairy = _ConnectionRecord.checkout(pool)
  File "C:\Users\Bala\AppData\Roaming\Python\Python313\site-packages\sqlalchemy\pool\base.py", line 711, in checkout
    rec = pool._do_get()
  File "C:\Users\Bala\AppData\Roaming\Python\Python313\site-packages\sqlalchemy\pool\impl.py", line 177, in _do_get
    with util.safe_reraise():
         ~~~~~~~~~~~~~~~~~^^
  File "C:\Users\Bala\AppData\Roaming\Python\Python313\site-packages\sqlalchemy\util\langhelpers.py", line 224, in __exit__
    raise exc_value.with_traceback(exc_tb)
  File "C:\Users\Bala\AppData\Roaming\Python\Python313\site-packages\sqlalchemy\pool\impl.py", line 175, in _do_get
    return self._create_connection()
           ~~~~~~~~~~~~~~~~~~~~~~~^^
  File "C:\Users\Bala\AppData\Roaming\Python\Python313\site-packages\sqlalchemy\pool\base.py", line 388, in _create_connection
    return _ConnectionRecord(self)
  File "C:\Users\Bala\AppData\Roaming\Python\Python313\site-packages\sqlalchemy\pool\base.py", line 673, in __init__
    self.__connect()
    ~~~~~~~~~~~~~~^^
  File "C:\Users\Bala\AppData\Roaming\Python\Python313\site-packages\sqlalchemy\pool\base.py", line 899, in __connect
    with util.safe_reraise():
         ~~~~~~~~~~~~~~~~~^^
  File "C:\Users\Bala\AppData\Roaming\Python\Python313\site-packages\sqlalchemy\util\langhelpers.py", line 224, in __exit__
    raise exc_value.with_traceback(exc_tb)
  File "C:\Users\Bala\AppData\Roaming\Python\Python313\site-packages\sqlalchemy\pool\base.py", line 895, in __connect
    self.dbapi_connection = connection = pool._invoke_creator(self)
                                         ~~~~~~~~~~~~~~~~~~~~^^^^^^
  File "C:\Users\Bala\AppData\Roaming\Python\Python313\site-packages\sqlalchemy\engine\create.py", line 661, in connect
    return dialect.connect(*cargs, **cparams)
           ~~~~~~~~~~~~~~~^^^^^^^^^^^^^^^^^^^
  File "C:\Users\Bala\AppData\Roaming\Python\Python313\site-packages\sqlalchemy\engine\default.py", line 629, in connect
    return self.loaded_dbapi.connect(*cargs, **cparams)  # type: ignore[no-any-return]  # NOQA: E501
           ~~~~~~~~~~~~~~~~~~~~~~~~~^^^^^^^^^^^^^^^^^^^
  File "C:\Users\Bala\AppData\Roaming\Python\Python313\site-packages\psycopg2\__init__.py", line 135, in connect
    conn = _connect(dsn, connection_factory=connection_factory, **kwasync)
sqlalchemy.exc.OperationalError: (psycopg2.OperationalError) connection to server at "localhost" (::1), port 5432 failed: FATAL:  password authentication failed for user "postgres"

(Background on this error at: https://sqlalche.me/e/20/e3q8)
2025-09-20 14:23:46,386 [INFO] app: 📝 Logging configured (level=DEBUG)
2025-09-20 14:23:46,387 [INFO] app: 🔗 Database URI: postgresql+psycopg2://postgres:****@localhost:5432/budget_db
2025-09-20 14:23:46,515 [INFO] app: 🌍 CORS enabled for origins: http://localhost:5173, http://127.0.0.1:5173
2025-09-20 14:23:46,527 [INFO] app: 🧩 Blueprints registered: ['auth', 'budget', 'home']
2025-09-20 14:23:46,537 [INFO] app: ⏰ Scheduler started successfully
2025-09-20 14:23:46,538 [INFO] app: 🚀 Starting Budget Tracker API at http://127.0.0.1:5000 (debug=False)
2025-09-20 14:37:27,572 [INFO] app: 📝 Logging configured (level=INFO)
2025-09-20 14:37:27,576 [INFO] app: 🔗 Database URI: postgresql+psycopg2://postgres:****@localhost:5432/budget_db
2025-09-20 14:37:27,891 [INFO] app: 🌍 CORS enabled for origins: http://localhost:5173, http://127.0.0.1:5173
2025-09-20 14:37:27,986 [INFO] app: 🧩 Blueprints registered: ['auth', 'budget', 'home']
2025-09-20 14:37:28,119 [INFO] app: ⏰ Scheduler started successfully
2025-09-20 14:39:25,415 [INFO] app: 📝 Logging configured (level=INFO)
2025-09-20 14:39:25,417 [INFO] app: 🔗 Database URI: postgresql+psycopg2://postgres:****@localhost:5432/budget_db
2025-09-20 14:39:25,536 [INFO] app: 🌍 CORS enabled for origins: http://localhost:5173, http://127.0.0.1:5173
2025-09-20 14:39:25,575 [INFO] app: 🧩 Blueprints registered: ['auth', 'budget', 'home']
2025-09-20 14:39:25,626 [INFO] app: ⏰ Scheduler started successfully
2025-09-20 14:41:24,758 [INFO] app: 📝 Logging configured (level=INFO)
2025-09-20 14:41:24,759 [INFO] app: 🔗 Database URI: postgresql+psycopg2://postgres:****@localhost:5432/budget_db
2025-09-20 14:41:24,834 [INFO] app: 🌍 CORS enabled for origins: http://localhost:5173, http://127.0.0.1:5173
2025-09-20 14:41:24,849 [INFO] app: 🧩 Blueprints registered: ['auth', 'budget', 'home']
2025-09-20 14:41:24,856 [INFO] app: ⏰ Scheduler started successfully
2025-09-20 14:41:32,211 [INFO] app: 📝 Logging configured (level=INFO)
2025-09-20 14:41:32,212 [INFO] app: 🔗 Database URI: postgresql+psycopg2://postgres:****@localhost:5432/budget_db
2025-09-20 14:41:32,428 [INFO] app: 🌍 CORS enabled for origins: http://localhost:5173, http://127.0.0.1:5173
2025-09-20 14:41:32,469 [INFO] app: 🧩 Blueprints registered: ['auth', 'budget', 'home']
2025-09-20 14:41:32,484 [INFO] app: ⏰ Scheduler started successfully
2025-09-20 14:59:43,110 [INFO] app: 📝 Logging configured (level=DEBUG)
2025-09-20 14:59:43,114 [INFO] app: 🔗 Database URI: postgresql+psycopg2://postgres:****@localhost:5432/budget_db
2025-09-20 14:59:43,249 [INFO] app: 🌍 CORS enabled for origins: http://localhost:5173, http://127.0.0.1:5173
2025-09-20 14:59:43,270 [INFO] app: 🧩 Blueprints registered: ['auth', 'budget', 'home']
2025-09-20 14:59:43,301 [INFO] app: ⏰ Scheduler started successfully
2025-09-20 14:59:43,303 [INFO] app: 🚀 Starting Budget Tracker API at http://127.0.0.1:5000 (debug=False)
2025-09-20 15:19:37,813 [INFO] app: 📝 Logging configured (level=DEBUG)
2025-09-20 15:19:37,815 [INFO] app: 🔗 Database URI: postgresql+psycopg2://postgres:****@localhost:5432/budget_db
2025-09-20 15:19:37,990 [INFO] app: 🌍 CORS enabled for origins: http://localhost:5173, http://127.0.0.1:5173
2025-09-20 15:19:38,018 [INFO] app: 🧩 Blueprints registered: ['auth', 'budget', 'home', 'trends']
2025-09-20 15:19:38,123 [INFO] app: ⏰ Scheduler started successfully
2025-09-20 15:19:38,125 [INFO] app: 🚀 Starting Budget Tracker API at http://127.0.0.1:5000 (debug=False)
2025-09-20 16:57:50,543 [INFO] app: 📝 Logging configured (level=DEBUG)
2025-09-20 16:57:50,546 [INFO] app: 🔗 Database URI: postgresql+psycopg2://postgres:****@localhost:5432/budget_db
2025-09-20 16:57:51,032 [INFO] app: 🌍 CORS enabled for origins: http://localhost:5173, http://127.0.0.1:5173
2025-09-20 16:57:51,054 [INFO] app: 🧩 Blueprints registered: ['auth', 'budget', 'home', 'trends']
2025-09-20 16:57:51,077 [INFO] app: ⏰ Scheduler started successfully
2025-09-20 16:57:51,078 [INFO] app: 🚀 Starting Budget Tracker API at http://127.0.0.1:5000 (debug=False)
2025-09-20 21:47:18,451 [INFO] app: 📝 Logging configured (level=DEBUG)
2025-09-20 21:47:18,455 [INFO] app: 🔗 Database URI: postgresql+psycopg2://postgres:****@localhost:5432/budget_db
2025-09-20 21:47:20,505 [INFO] app: 🌍 CORS enabled for: http://localhost:5173, http://127.0.0.1:5173
2025-09-20 21:47:20,544 [INFO] app: 🧩 Blueprints registered: ['auth', 'budget', 'expense_bp', 'salary', 'trends', 'home']
2025-09-20 21:47:20,545 [ERROR] app: ⚠️ Failed to start scheduler: 'BackgroundScheduler' object has no attribute 'init_app'
Traceback (most recent call last):
  File "D:\AI Budget_Tracker_Backend\BudgetTracker_Backend\app.py", line 160, in _configure_scheduler
    scheduler.init_app(app)
    ^^^^^^^^^^^^^^^^^^
AttributeError: 'BackgroundScheduler' object has no attribute 'init_app'
2025-09-20 21:47:20,568 [INFO] app: 🚀 Starting Budget Tracker API at http://127.0.0.1:5000 (debug=False)
2025-09-21 09:06:27,398 [INFO] app: 📝 Logging configured (level=DEBUG)
2025-09-21 09:06:27,400 [INFO] app: 🔗 Database URI: postgresql+psycopg2://postgres:****@localhost:5432/budget_db
2025-09-21 09:06:27,568 [INFO] app: 🌍 CORS enabled for: http://localhost:5173, http://127.0.0.1:5173
2025-09-21 09:06:27,578 [INFO] app: 🧩 Blueprints registered: ['auth', 'budget', 'expense', 'salary', 'trends', 'home']
2025-09-21 09:06:27,581 [ERROR] app: ⚠️ Failed to start scheduler: 'BackgroundScheduler' object has no attribute 'init_app'
Traceback (most recent call last):
  File "D:\AI Budget_Tracker_Backend\BudgetTracker_Backend\app.py", line 162, in _configure_scheduler
    scheduler.init_app(app)
    ^^^^^^^^^^^^^^^^^^
AttributeError: 'BackgroundScheduler' object has no attribute 'init_app'
2025-09-21 09:06:27,586 [INFO] app: 🚀 Starting Budget Tracker API at http://127.0.0.1:5000 (debug=False)
2025-09-21 09:15:14,352 [INFO] app: 📝 Logging configured (level=DEBUG)
2025-09-21 09:15:14,353 [INFO] app: 🔗 Database URI: postgresql+psycopg2://postgres:****@localhost:5432/budget_db
2025-09-21 09:15:14,419 [INFO] app: ✅ SQLAlchemy initialized
2025-09-21 09:15:14,423 [INFO] app: ✅ Flask-Migrate initialized
2025-09-21 09:15:14,424 [INFO] app: ✅ Flask-Mail initialized
2025-09-21 09:15:14,424 [INFO] app: 🌍 CORS enabled for: http://localhost:5173, http://127.0.0.1:5173
2025-09-21 09:15:14,437 [INFO] app: 🧩 Blueprints registered: ['auth', 'budget', 'expense', 'salary', 'trends', 'home']
2025-09-21 09:15:14,502 [INFO] app: ⏰ Scheduler started successfully
2025-09-21 09:15:14,503 [INFO] app: 🚀 Starting Budget Tracker API at http://127.0.0.1:5000 (debug=False)
2025-09-21 09:19:41,173 [INFO] app: 📝 Logging configured (level=DEBUG)
2025-09-21 09:19:41,176 [INFO] app: 🔗 Database URI: postgresql+psycopg2://postgres:****@localhost:5432/budget_db
2025-09-21 09:19:41,257 [INFO] app: ✅ SQLAlchemy initialized
2025-09-21 09:19:41,265 [INFO] app: ✅ Flask-Migrate initialized
2025-09-21 09:19:41,266 [INFO] app: ✅ Flask-Mail initialized
2025-09-21 09:19:41,266 [INFO] app: 🌍 CORS enabled for: http://localhost:5173, http://127.0.0.1:5173
2025-09-21 09:19:41,284 [INFO] app: 🧩 Blueprints registered: ['auth', 'budget', 'expense', 'salary', 'trends', 'home']
2025-09-21 09:19:41,429 [INFO] app: ⏰ Scheduler started successfully
2025-09-21 09:19:41,563 [INFO] app: 🚀 Starting Budget Tracker API at http://127.0.0.1:5000 (debug=False)
2025-09-21 09:19:51,437 [INFO] app: ✅ Scheduler sample job executed.
2025-09-21 09:20:01,671 [INFO] app: ✅ Scheduler sample job executed.
2025-09-21 09:20:11,457 [INFO] app: ✅ Scheduler sample job executed.
2025-09-21 09:20:21,448 [INFO] app: ✅ Scheduler sample job executed.
2025-09-21 09:20:31,367 [INFO] app: ✅ Scheduler sample job executed.
2025-09-21 09:20:41,360 [INFO] app: ✅ Scheduler sample job executed.
2025-09-21 09:20:51,365 [INFO] app: ✅ Scheduler sample job executed.
2025-09-21 09:21:01,341 [INFO] app: ✅ Scheduler sample job executed.
2025-09-21 09:21:11,347 [INFO] app: ✅ Scheduler sample job executed.
2025-09-21 09:21:21,352 [INFO] app: ✅ Scheduler sample job executed.
2025-09-21 09:21:31,354 [INFO] app: ✅ Scheduler sample job executed.
2025-09-21 09:21:41,346 [INFO] app: ✅ Scheduler sample job executed.
2025-09-21 09:21:51,342 [INFO] app: ✅ Scheduler sample job executed.
2025-09-21 09:22:01,344 [INFO] app: ✅ Scheduler sample job executed.
2025-09-21 09:22:11,356 [INFO] app: ✅ Scheduler sample job executed.
2025-09-21 09:22:21,361 [INFO] app: ✅ Scheduler sample job executed.
